[2020-10-20 05:14:53 +0000] [1284] [INFO] Starting gunicorn 20.0.4
[2020-10-20 05:14:53 +0000] [1284] [INFO] Listening at: http://0.0.0.0:5000 (1284)
[2020-10-20 05:14:53 +0000] [1284] [INFO] Using worker: sync
[2020-10-20 05:14:53 +0000] [1290] [INFO] Booting worker with pid: 1290
[2020-10-20 05:14:53 +0000] [1292] [INFO] Booting worker with pid: 1292
[2020-10-20 05:14:54 +0000] [1294] [INFO] Booting worker with pid: 1294
[2020-10-20 05:14:54 +0000] [1295] [INFO] Booting worker with pid: 1295
[2020-10-20 05:14:54 +0000] [1300] [INFO] Booting worker with pid: 1300
[2020-10-20 05:14:54 +0000] [1301] [INFO] Booting worker with pid: 1301
[2020-10-20 05:15:24 +0000] [1284] [CRITICAL] WORKER TIMEOUT (pid:1294)
[2020-10-20 05:15:24 +0000] [1294] [INFO] Worker exiting (pid: 1294)
[2020-10-20 05:15:24 +0000] [1310] [INFO] Booting worker with pid: 1310
[2020-10-20 05:23:19 +0000] [1285] [INFO] Starting gunicorn 20.0.4
[2020-10-20 05:23:19 +0000] [1285] [INFO] Listening at: http://0.0.0.0:5000 (1285)
[2020-10-20 05:23:19 +0000] [1285] [INFO] Using worker: sync
[2020-10-20 05:23:19 +0000] [1291] [INFO] Booting worker with pid: 1291
[2020-10-20 05:23:19 +0000] [1291] [ERROR] Exception in worker process
Traceback (most recent call last):
  File "/usr/local/lib/python3.6/dist-packages/gunicorn/arbiter.py", line 583, in spawn_worker
    worker.init_process()
  File "/usr/local/lib/python3.6/dist-packages/gunicorn/workers/base.py", line 119, in init_process
    self.load_wsgi()
  File "/usr/local/lib/python3.6/dist-packages/gunicorn/workers/base.py", line 144, in load_wsgi
    self.wsgi = self.app.wsgi()
  File "/usr/local/lib/python3.6/dist-packages/gunicorn/app/base.py", line 67, in wsgi
    self.callable = self.load()
  File "/usr/local/lib/python3.6/dist-packages/gunicorn/app/wsgiapp.py", line 49, in load
    return self.load_wsgiapp()
  File "/usr/local/lib/python3.6/dist-packages/gunicorn/app/wsgiapp.py", line 39, in load_wsgiapp
    return util.import_app(self.app_uri)
  File "/usr/local/lib/python3.6/dist-packages/gunicorn/util.py", line 358, in import_app
    mod = importlib.import_module(module)
  File "/usr/lib/python3.6/importlib/__init__.py", line 126, in import_module
    return _bootstrap._gcd_import(name[level:], package, level)
  File "<frozen importlib._bootstrap>", line 994, in _gcd_import
  File "<frozen importlib._bootstrap>", line 971, in _find_and_load
  File "<frozen importlib._bootstrap>", line 955, in _find_and_load_unlocked
  File "<frozen importlib._bootstrap>", line 665, in _load_unlocked
  File "<frozen importlib._bootstrap_external>", line 674, in exec_module
  File "<frozen importlib._bootstrap_external>", line 781, in get_code
  File "<frozen importlib._bootstrap_external>", line 741, in source_to_code
  File "<frozen importlib._bootstrap>", line 219, in _call_with_frames_removed
  File "/root/flask_api_demo/app.py", line 24
    f.write(r.content)
    ^
IndentationError: expected an indented block
[2020-10-20 05:23:19 +0000] [1291] [INFO] Worker exiting (pid: 1291)
[2020-10-20 05:23:19 +0000] [1285] [INFO] Shutting down: Master
[2020-10-20 05:23:19 +0000] [1285] [INFO] Reason: Worker failed to boot.
[2020-10-20 05:23:48 +0000] [1284] [INFO] Starting gunicorn 20.0.4
[2020-10-20 05:23:48 +0000] [1284] [INFO] Listening at: http://0.0.0.0:5000 (1284)
[2020-10-20 05:23:48 +0000] [1284] [INFO] Using worker: sync
[2020-10-20 05:23:48 +0000] [1290] [INFO] Booting worker with pid: 1290
[2020-10-20 05:23:48 +0000] [1291] [INFO] Booting worker with pid: 1291
[2020-10-20 05:23:48 +0000] [1292] [INFO] Booting worker with pid: 1292
[2020-10-20 05:23:48 +0000] [1296] [INFO] Booting worker with pid: 1296
[2020-10-20 05:23:48 +0000] [1298] [INFO] Booting worker with pid: 1298
[2020-10-20 05:23:48 +0000] [1302] [INFO] Booting worker with pid: 1302
[2020-10-20 05:23:54 +0000] [1291] [ERROR] Error handling request /?model=sam
Traceback (most recent call last):
  File "/usr/local/lib/python3.6/dist-packages/gunicorn/workers/sync.py", line 134, in handle
    self.handle_request(listener, req, client, addr)
  File "/usr/local/lib/python3.6/dist-packages/gunicorn/workers/sync.py", line 175, in handle_request
    respiter = self.wsgi(environ, resp.start_response)
  File "/usr/local/lib/python3.6/dist-packages/flask/app.py", line 2464, in __call__
    return self.wsgi_app(environ, start_response)
  File "/usr/local/lib/python3.6/dist-packages/flask/app.py", line 2450, in wsgi_app
    response = self.handle_exception(e)
  File "/usr/local/lib/python3.6/dist-packages/flask/app.py", line 1867, in handle_exception
    reraise(exc_type, exc_value, tb)
  File "/usr/local/lib/python3.6/dist-packages/flask/_compat.py", line 39, in reraise
    raise value
  File "/usr/local/lib/python3.6/dist-packages/flask/app.py", line 2447, in wsgi_app
    response = self.full_dispatch_request()
  File "/usr/local/lib/python3.6/dist-packages/flask/app.py", line 1952, in full_dispatch_request
    rv = self.handle_user_exception(e)
  File "/usr/local/lib/python3.6/dist-packages/flask/app.py", line 1821, in handle_user_exception
    reraise(exc_type, exc_value, tb)
  File "/usr/local/lib/python3.6/dist-packages/flask/_compat.py", line 39, in reraise
    raise value
  File "/usr/local/lib/python3.6/dist-packages/flask/app.py", line 1950, in full_dispatch_request
    rv = self.dispatch_request()
  File "/usr/local/lib/python3.6/dist-packages/flask/app.py", line 1936, in dispatch_request
    return self.view_functions[rule.endpoint](**req.view_args)
  File "/root/flask_api_demo/app.py", line 24, in index
    f.write(r.content)
UnboundLocalError: local variable 'r' referenced before assignment
[2020-10-20 05:23:57 +0000] [1290] [ERROR] Error handling request /?model=ex
Traceback (most recent call last):
  File "/usr/local/lib/python3.6/dist-packages/gunicorn/workers/sync.py", line 134, in handle
    self.handle_request(listener, req, client, addr)
  File "/usr/local/lib/python3.6/dist-packages/gunicorn/workers/sync.py", line 175, in handle_request
    respiter = self.wsgi(environ, resp.start_response)
  File "/usr/local/lib/python3.6/dist-packages/flask/app.py", line 2464, in __call__
    return self.wsgi_app(environ, start_response)
  File "/usr/local/lib/python3.6/dist-packages/flask/app.py", line 2450, in wsgi_app
    response = self.handle_exception(e)
  File "/usr/local/lib/python3.6/dist-packages/flask/app.py", line 1867, in handle_exception
    reraise(exc_type, exc_value, tb)
  File "/usr/local/lib/python3.6/dist-packages/flask/_compat.py", line 39, in reraise
    raise value
  File "/usr/local/lib/python3.6/dist-packages/flask/app.py", line 2447, in wsgi_app
    response = self.full_dispatch_request()
  File "/usr/local/lib/python3.6/dist-packages/flask/app.py", line 1952, in full_dispatch_request
    rv = self.handle_user_exception(e)
  File "/usr/local/lib/python3.6/dist-packages/flask/app.py", line 1821, in handle_user_exception
    reraise(exc_type, exc_value, tb)
  File "/usr/local/lib/python3.6/dist-packages/flask/_compat.py", line 39, in reraise
    raise value
  File "/usr/local/lib/python3.6/dist-packages/flask/app.py", line 1950, in full_dispatch_request
    rv = self.dispatch_request()
  File "/usr/local/lib/python3.6/dist-packages/flask/app.py", line 1936, in dispatch_request
    return self.view_functions[rule.endpoint](**req.view_args)
  File "/root/flask_api_demo/app.py", line 22, in index
    r = requests.get('https://www.google.com/images/srpr/logo11w.png')
NameError: name 'requests' is not defined
[2020-10-20 05:25:00 +0000] [1285] [INFO] Starting gunicorn 20.0.4
[2020-10-20 05:25:00 +0000] [1285] [INFO] Listening at: http://0.0.0.0:5000 (1285)
[2020-10-20 05:25:00 +0000] [1285] [INFO] Using worker: sync
[2020-10-20 05:25:00 +0000] [1291] [INFO] Booting worker with pid: 1291
[2020-10-20 05:25:00 +0000] [1292] [INFO] Booting worker with pid: 1292
[2020-10-20 05:25:00 +0000] [1293] [INFO] Booting worker with pid: 1293
[2020-10-20 05:25:00 +0000] [1296] [INFO] Booting worker with pid: 1296
[2020-10-20 05:25:01 +0000] [1299] [INFO] Booting worker with pid: 1299
[2020-10-20 05:25:01 +0000] [1303] [INFO] Booting worker with pid: 1303
[2020-10-20 05:25:03 +0000] [1303] [ERROR] Error handling request /?model=ex
Traceback (most recent call last):
  File "/usr/local/lib/python3.6/dist-packages/gunicorn/workers/sync.py", line 134, in handle
    self.handle_request(listener, req, client, addr)
  File "/usr/local/lib/python3.6/dist-packages/gunicorn/workers/sync.py", line 175, in handle_request
    respiter = self.wsgi(environ, resp.start_response)
  File "/usr/local/lib/python3.6/dist-packages/flask/app.py", line 2464, in __call__
    return self.wsgi_app(environ, start_response)
  File "/usr/local/lib/python3.6/dist-packages/flask/app.py", line 2450, in wsgi_app
    response = self.handle_exception(e)
  File "/usr/local/lib/python3.6/dist-packages/flask/app.py", line 1867, in handle_exception
    reraise(exc_type, exc_value, tb)
  File "/usr/local/lib/python3.6/dist-packages/flask/_compat.py", line 39, in reraise
    raise value
  File "/usr/local/lib/python3.6/dist-packages/flask/app.py", line 2447, in wsgi_app
    response = self.full_dispatch_request()
  File "/usr/local/lib/python3.6/dist-packages/flask/app.py", line 1952, in full_dispatch_request
    rv = self.handle_user_exception(e)
  File "/usr/local/lib/python3.6/dist-packages/flask/app.py", line 1821, in handle_user_exception
    reraise(exc_type, exc_value, tb)
  File "/usr/local/lib/python3.6/dist-packages/flask/_compat.py", line 39, in reraise
    raise value
  File "/usr/local/lib/python3.6/dist-packages/flask/app.py", line 1950, in full_dispatch_request
    rv = self.dispatch_request()
  File "/usr/local/lib/python3.6/dist-packages/flask/app.py", line 1936, in dispatch_request
    return self.view_functions[rule.endpoint](**req.view_args)
  File "/root/flask_api_demo/app.py", line 22, in index
    r = requests.get('https://www.google.com/images/srpr/logo11w.png')
NameError: name 'requests' is not defined
[2020-10-20 05:25:14 +0000] [1296] [ERROR] Error handling request /?model=ex
Traceback (most recent call last):
  File "/usr/local/lib/python3.6/dist-packages/gunicorn/workers/sync.py", line 134, in handle
    self.handle_request(listener, req, client, addr)
  File "/usr/local/lib/python3.6/dist-packages/gunicorn/workers/sync.py", line 175, in handle_request
    respiter = self.wsgi(environ, resp.start_response)
  File "/usr/local/lib/python3.6/dist-packages/flask/app.py", line 2464, in __call__
    return self.wsgi_app(environ, start_response)
  File "/usr/local/lib/python3.6/dist-packages/flask/app.py", line 2450, in wsgi_app
    response = self.handle_exception(e)
  File "/usr/local/lib/python3.6/dist-packages/flask/app.py", line 1867, in handle_exception
    reraise(exc_type, exc_value, tb)
  File "/usr/local/lib/python3.6/dist-packages/flask/_compat.py", line 39, in reraise
    raise value
  File "/usr/local/lib/python3.6/dist-packages/flask/app.py", line 2447, in wsgi_app
    response = self.full_dispatch_request()
  File "/usr/local/lib/python3.6/dist-packages/flask/app.py", line 1952, in full_dispatch_request
    rv = self.handle_user_exception(e)
  File "/usr/local/lib/python3.6/dist-packages/flask/app.py", line 1821, in handle_user_exception
    reraise(exc_type, exc_value, tb)
  File "/usr/local/lib/python3.6/dist-packages/flask/_compat.py", line 39, in reraise
    raise value
  File "/usr/local/lib/python3.6/dist-packages/flask/app.py", line 1950, in full_dispatch_request
    rv = self.dispatch_request()
  File "/usr/local/lib/python3.6/dist-packages/flask/app.py", line 1936, in dispatch_request
    return self.view_functions[rule.endpoint](**req.view_args)
  File "/root/flask_api_demo/app.py", line 22, in index
    r = requests.get('https://www.google.com/images/srpr/logo11w.png')
NameError: name 'requests' is not defined
[2020-10-20 05:25:47 +0000] [1285] [CRITICAL] WORKER TIMEOUT (pid:1291)
[2020-10-20 05:25:47 +0000] [1285] [CRITICAL] WORKER TIMEOUT (pid:1303)
[2020-10-20 05:25:47 +0000] [1291] [INFO] Worker exiting (pid: 1291)
[2020-10-20 05:25:47 +0000] [1303] [INFO] Worker exiting (pid: 1303)
[2020-10-20 05:25:47 +0000] [1315] [INFO] Booting worker with pid: 1315
[2020-10-20 05:25:47 +0000] [1316] [INFO] Booting worker with pid: 1316
[2020-10-20 05:26:06 +0000] [1286] [INFO] Starting gunicorn 20.0.4
[2020-10-20 05:26:06 +0000] [1286] [INFO] Listening at: http://0.0.0.0:5000 (1286)
[2020-10-20 05:26:06 +0000] [1286] [INFO] Using worker: sync
[2020-10-20 05:26:06 +0000] [1292] [INFO] Booting worker with pid: 1292
[2020-10-20 05:26:06 +0000] [1293] [INFO] Booting worker with pid: 1293
[2020-10-20 05:26:06 +0000] [1296] [INFO] Booting worker with pid: 1296
[2020-10-20 05:26:06 +0000] [1297] [INFO] Booting worker with pid: 1297
[2020-10-20 05:26:06 +0000] [1298] [INFO] Booting worker with pid: 1298
[2020-10-20 05:26:06 +0000] [1299] [INFO] Booting worker with pid: 1299
[2020-10-20 05:26:38 +0000] [1286] [CRITICAL] WORKER TIMEOUT (pid:1292)
[2020-10-20 05:26:38 +0000] [1292] [INFO] Worker exiting (pid: 1292)
[2020-10-20 05:26:38 +0000] [1312] [INFO] Booting worker with pid: 1312
[2020-10-20 05:27:55 +0000] [1285] [INFO] Starting gunicorn 20.0.4
[2020-10-20 05:27:55 +0000] [1285] [INFO] Listening at: http://0.0.0.0:5000 (1285)
[2020-10-20 05:27:55 +0000] [1285] [INFO] Using worker: sync
[2020-10-20 05:27:55 +0000] [1291] [INFO] Booting worker with pid: 1291
[2020-10-20 05:27:55 +0000] [1292] [INFO] Booting worker with pid: 1292
[2020-10-20 05:27:55 +0000] [1294] [INFO] Booting worker with pid: 1294
[2020-10-20 05:27:55 +0000] [1296] [INFO] Booting worker with pid: 1296
[2020-10-20 05:27:55 +0000] [1298] [INFO] Booting worker with pid: 1298
[2020-10-20 05:27:55 +0000] [1300] [INFO] Booting worker with pid: 1300
[2020-10-20 05:28:01 +0000] [1298] [ERROR] Error handling request /?model=ex
Traceback (most recent call last):
  File "/usr/local/lib/python3.6/dist-packages/gunicorn/workers/sync.py", line 134, in handle
    self.handle_request(listener, req, client, addr)
  File "/usr/local/lib/python3.6/dist-packages/gunicorn/workers/sync.py", line 175, in handle_request
    respiter = self.wsgi(environ, resp.start_response)
  File "/usr/local/lib/python3.6/dist-packages/flask/app.py", line 2464, in __call__
    return self.wsgi_app(environ, start_response)
  File "/usr/local/lib/python3.6/dist-packages/flask/app.py", line 2450, in wsgi_app
    response = self.handle_exception(e)
  File "/usr/local/lib/python3.6/dist-packages/flask/app.py", line 1867, in handle_exception
    reraise(exc_type, exc_value, tb)
  File "/usr/local/lib/python3.6/dist-packages/flask/_compat.py", line 39, in reraise
    raise value
  File "/usr/local/lib/python3.6/dist-packages/flask/app.py", line 2447, in wsgi_app
    response = self.full_dispatch_request()
  File "/usr/local/lib/python3.6/dist-packages/flask/app.py", line 1952, in full_dispatch_request
    rv = self.handle_user_exception(e)
  File "/usr/local/lib/python3.6/dist-packages/flask/app.py", line 1821, in handle_user_exception
    reraise(exc_type, exc_value, tb)
  File "/usr/local/lib/python3.6/dist-packages/flask/_compat.py", line 39, in reraise
    raise value
  File "/usr/local/lib/python3.6/dist-packages/flask/app.py", line 1950, in full_dispatch_request
    rv = self.dispatch_request()
  File "/usr/local/lib/python3.6/dist-packages/flask/app.py", line 1936, in dispatch_request
    return self.view_functions[rule.endpoint](**req.view_args)
  File "/root/flask_api_demo/app.py", line 22, in index
    r = requests.get('https://www.google.com/images/srpr/logo11w.png')
NameError: name 'requests' is not defined
[2020-10-20 05:28:35 +0000] [1285] [CRITICAL] WORKER TIMEOUT (pid:1296)
[2020-10-20 05:28:35 +0000] [1296] [INFO] Worker exiting (pid: 1296)
[2020-10-20 05:28:35 +0000] [1313] [INFO] Booting worker with pid: 1313
[2020-10-20 05:30:11 +0000] [1285] [INFO] Starting gunicorn 20.0.4
[2020-10-20 05:30:11 +0000] [1285] [INFO] Listening at: http://0.0.0.0:5000 (1285)
[2020-10-20 05:30:11 +0000] [1285] [INFO] Using worker: sync
[2020-10-20 05:30:11 +0000] [1291] [INFO] Booting worker with pid: 1291
[2020-10-20 05:30:11 +0000] [1293] [INFO] Booting worker with pid: 1293
[2020-10-20 05:30:11 +0000] [1295] [INFO] Booting worker with pid: 1295
[2020-10-20 05:30:11 +0000] [1296] [INFO] Booting worker with pid: 1296
[2020-10-20 05:30:11 +0000] [1297] [INFO] Booting worker with pid: 1297
[2020-10-20 05:30:11 +0000] [1302] [INFO] Booting worker with pid: 1302
[2020-10-20 05:30:12 +0000] [1295] [ERROR] Error handling request /
Traceback (most recent call last):
  File "/usr/local/lib/python3.6/dist-packages/gunicorn/workers/sync.py", line 134, in handle
    self.handle_request(listener, req, client, addr)
  File "/usr/local/lib/python3.6/dist-packages/gunicorn/workers/sync.py", line 175, in handle_request
    respiter = self.wsgi(environ, resp.start_response)
  File "/usr/local/lib/python3.6/dist-packages/flask/app.py", line 2464, in __call__
    return self.wsgi_app(environ, start_response)
  File "/usr/local/lib/python3.6/dist-packages/flask/app.py", line 2450, in wsgi_app
    response = self.handle_exception(e)
  File "/usr/local/lib/python3.6/dist-packages/flask/app.py", line 1867, in handle_exception
    reraise(exc_type, exc_value, tb)
  File "/usr/local/lib/python3.6/dist-packages/flask/_compat.py", line 39, in reraise
    raise value
  File "/usr/local/lib/python3.6/dist-packages/flask/app.py", line 2447, in wsgi_app
    response = self.full_dispatch_request()
  File "/usr/local/lib/python3.6/dist-packages/flask/app.py", line 1952, in full_dispatch_request
    rv = self.handle_user_exception(e)
  File "/usr/local/lib/python3.6/dist-packages/flask/app.py", line 1821, in handle_user_exception
    reraise(exc_type, exc_value, tb)
  File "/usr/local/lib/python3.6/dist-packages/flask/_compat.py", line 39, in reraise
    raise value
  File "/usr/local/lib/python3.6/dist-packages/flask/app.py", line 1950, in full_dispatch_request
    rv = self.dispatch_request()
  File "/usr/local/lib/python3.6/dist-packages/flask/app.py", line 1936, in dispatch_request
    return self.view_functions[rule.endpoint](**req.view_args)
  File "/root/flask_api_demo/app.py", line 20, in index
    x = request.args.get["model"]
TypeError: 'method' object is not subscriptable
[2020-10-20 05:30:14 +0000] [1295] [ERROR] Error handling request /?model=sam
Traceback (most recent call last):
  File "/usr/local/lib/python3.6/dist-packages/gunicorn/workers/sync.py", line 134, in handle
    self.handle_request(listener, req, client, addr)
  File "/usr/local/lib/python3.6/dist-packages/gunicorn/workers/sync.py", line 175, in handle_request
    respiter = self.wsgi(environ, resp.start_response)
  File "/usr/local/lib/python3.6/dist-packages/flask/app.py", line 2464, in __call__
    return self.wsgi_app(environ, start_response)
  File "/usr/local/lib/python3.6/dist-packages/flask/app.py", line 2450, in wsgi_app
    response = self.handle_exception(e)
  File "/usr/local/lib/python3.6/dist-packages/flask/app.py", line 1867, in handle_exception
    reraise(exc_type, exc_value, tb)
  File "/usr/local/lib/python3.6/dist-packages/flask/_compat.py", line 39, in reraise
    raise value
  File "/usr/local/lib/python3.6/dist-packages/flask/app.py", line 2447, in wsgi_app
    response = self.full_dispatch_request()
  File "/usr/local/lib/python3.6/dist-packages/flask/app.py", line 1952, in full_dispatch_request
    rv = self.handle_user_exception(e)
  File "/usr/local/lib/python3.6/dist-packages/flask/app.py", line 1821, in handle_user_exception
    reraise(exc_type, exc_value, tb)
  File "/usr/local/lib/python3.6/dist-packages/flask/_compat.py", line 39, in reraise
    raise value
  File "/usr/local/lib/python3.6/dist-packages/flask/app.py", line 1950, in full_dispatch_request
    rv = self.dispatch_request()
  File "/usr/local/lib/python3.6/dist-packages/flask/app.py", line 1936, in dispatch_request
    return self.view_functions[rule.endpoint](**req.view_args)
  File "/root/flask_api_demo/app.py", line 20, in index
    x = request.args.get["model"]
TypeError: 'method' object is not subscriptable
[2020-10-20 05:30:21 +0000] [1297] [ERROR] Error handling request /?model=ex
Traceback (most recent call last):
  File "/usr/local/lib/python3.6/dist-packages/gunicorn/workers/sync.py", line 134, in handle
    self.handle_request(listener, req, client, addr)
  File "/usr/local/lib/python3.6/dist-packages/gunicorn/workers/sync.py", line 175, in handle_request
    respiter = self.wsgi(environ, resp.start_response)
  File "/usr/local/lib/python3.6/dist-packages/flask/app.py", line 2464, in __call__
    return self.wsgi_app(environ, start_response)
  File "/usr/local/lib/python3.6/dist-packages/flask/app.py", line 2450, in wsgi_app
    response = self.handle_exception(e)
  File "/usr/local/lib/python3.6/dist-packages/flask/app.py", line 1867, in handle_exception
    reraise(exc_type, exc_value, tb)
  File "/usr/local/lib/python3.6/dist-packages/flask/_compat.py", line 39, in reraise
    raise value
  File "/usr/local/lib/python3.6/dist-packages/flask/app.py", line 2447, in wsgi_app
    response = self.full_dispatch_request()
  File "/usr/local/lib/python3.6/dist-packages/flask/app.py", line 1952, in full_dispatch_request
    rv = self.handle_user_exception(e)
  File "/usr/local/lib/python3.6/dist-packages/flask/app.py", line 1821, in handle_user_exception
    reraise(exc_type, exc_value, tb)
  File "/usr/local/lib/python3.6/dist-packages/flask/_compat.py", line 39, in reraise
    raise value
  File "/usr/local/lib/python3.6/dist-packages/flask/app.py", line 1950, in full_dispatch_request
    rv = self.dispatch_request()
  File "/usr/local/lib/python3.6/dist-packages/flask/app.py", line 1936, in dispatch_request
    return self.view_functions[rule.endpoint](**req.view_args)
  File "/root/flask_api_demo/app.py", line 20, in index
    x = request.args.get["model"]
TypeError: 'method' object is not subscriptable
[2020-10-20 05:32:25 +0000] [1284] [INFO] Starting gunicorn 20.0.4
[2020-10-20 05:32:25 +0000] [1284] [INFO] Listening at: http://0.0.0.0:5000 (1284)
[2020-10-20 05:32:25 +0000] [1284] [INFO] Using worker: sync
[2020-10-20 05:32:25 +0000] [1290] [INFO] Booting worker with pid: 1290
[2020-10-20 05:32:25 +0000] [1291] [INFO] Booting worker with pid: 1291
[2020-10-20 05:32:25 +0000] [1292] [INFO] Booting worker with pid: 1292
[2020-10-20 05:32:25 +0000] [1296] [INFO] Booting worker with pid: 1296
[2020-10-20 05:32:25 +0000] [1298] [INFO] Booting worker with pid: 1298
[2020-10-20 05:32:25 +0000] [1302] [INFO] Booting worker with pid: 1302
[2020-10-20 05:32:25 +0000] [1296] [ERROR] Error handling request /?model=ex
Traceback (most recent call last):
  File "/usr/local/lib/python3.6/dist-packages/gunicorn/workers/sync.py", line 134, in handle
    self.handle_request(listener, req, client, addr)
  File "/usr/local/lib/python3.6/dist-packages/gunicorn/workers/sync.py", line 175, in handle_request
    respiter = self.wsgi(environ, resp.start_response)
  File "/usr/local/lib/python3.6/dist-packages/flask/app.py", line 2464, in __call__
    return self.wsgi_app(environ, start_response)
  File "/usr/local/lib/python3.6/dist-packages/flask/app.py", line 2450, in wsgi_app
    response = self.handle_exception(e)
  File "/usr/local/lib/python3.6/dist-packages/flask/app.py", line 1867, in handle_exception
    reraise(exc_type, exc_value, tb)
  File "/usr/local/lib/python3.6/dist-packages/flask/_compat.py", line 39, in reraise
    raise value
  File "/usr/local/lib/python3.6/dist-packages/flask/app.py", line 2447, in wsgi_app
    response = self.full_dispatch_request()
  File "/usr/local/lib/python3.6/dist-packages/flask/app.py", line 1952, in full_dispatch_request
    rv = self.handle_user_exception(e)
  File "/usr/local/lib/python3.6/dist-packages/flask/app.py", line 1821, in handle_user_exception
    reraise(exc_type, exc_value, tb)
  File "/usr/local/lib/python3.6/dist-packages/flask/_compat.py", line 39, in reraise
    raise value
  File "/usr/local/lib/python3.6/dist-packages/flask/app.py", line 1950, in full_dispatch_request
    rv = self.dispatch_request()
  File "/usr/local/lib/python3.6/dist-packages/flask/app.py", line 1936, in dispatch_request
    return self.view_functions[rule.endpoint](**req.view_args)
  File "/root/flask_api_demo/app.py", line 22, in index
    r = requests.get('https://www.google.com/images/srpr/logo11w.png')
NameError: name 'requests' is not defined
[2020-10-20 05:33:00 +0000] [1284] [CRITICAL] WORKER TIMEOUT (pid:1291)
[2020-10-20 05:33:00 +0000] [1284] [CRITICAL] WORKER TIMEOUT (pid:1302)
[2020-10-20 05:33:00 +0000] [1291] [INFO] Worker exiting (pid: 1291)
[2020-10-20 05:33:00 +0000] [1302] [INFO] Worker exiting (pid: 1302)
[2020-10-20 05:33:00 +0000] [1310] [INFO] Booting worker with pid: 1310
[2020-10-20 05:33:00 +0000] [1312] [INFO] Booting worker with pid: 1312
[2020-10-20 05:36:21 +0000] [1285] [INFO] Starting gunicorn 20.0.4
[2020-10-20 05:36:21 +0000] [1285] [INFO] Listening at: http://0.0.0.0:5000 (1285)
[2020-10-20 05:36:21 +0000] [1285] [INFO] Using worker: sync
[2020-10-20 05:36:21 +0000] [1291] [INFO] Booting worker with pid: 1291
[2020-10-20 05:36:22 +0000] [1292] [INFO] Booting worker with pid: 1292
[2020-10-20 05:36:22 +0000] [1293] [INFO] Booting worker with pid: 1293
[2020-10-20 05:36:22 +0000] [1294] [INFO] Booting worker with pid: 1294
[2020-10-20 05:36:22 +0000] [1297] [INFO] Booting worker with pid: 1297
[2020-10-20 05:36:22 +0000] [1300] [INFO] Booting worker with pid: 1300
[2020-10-20 05:37:10 +0000] [1285] [CRITICAL] WORKER TIMEOUT (pid:1291)
[2020-10-20 05:37:10 +0000] [1285] [CRITICAL] WORKER TIMEOUT (pid:1297)
[2020-10-20 05:37:10 +0000] [1291] [INFO] Worker exiting (pid: 1291)
[2020-10-20 05:37:10 +0000] [1297] [INFO] Worker exiting (pid: 1297)
[2020-10-20 05:37:10 +0000] [1315] [INFO] Booting worker with pid: 1315
[2020-10-20 05:37:10 +0000] [1317] [INFO] Booting worker with pid: 1317
[2020-10-20 06:08:07 +0000] [1254] [INFO] Starting gunicorn 20.0.4
[2020-10-20 06:08:07 +0000] [1254] [INFO] Listening at: http://0.0.0.0:5000 (1254)
[2020-10-20 06:08:07 +0000] [1254] [INFO] Using worker: sync
[2020-10-20 06:08:07 +0000] [1261] [INFO] Booting worker with pid: 1261
[2020-10-20 06:08:07 +0000] [1262] [INFO] Booting worker with pid: 1262
[2020-10-20 06:08:07 +0000] [1264] [INFO] Booting worker with pid: 1264
[2020-10-20 06:08:07 +0000] [1254] [INFO] Starting gunicorn 20.0.4
[2020-10-20 06:08:07 +0000] [1254] [INFO] Listening at: http://0.0.0.0:5000 (1254)
[2020-10-20 06:08:07 +0000] [1254] [INFO] Using worker: sync
[2020-10-20 06:08:07 +0000] [1261] [INFO] Booting worker with pid: 1261
[2020-10-20 06:08:07 +0000] [1265] [INFO] Booting worker with pid: 1265
[2020-10-20 06:08:07 +0000] [1262] [INFO] Booting worker with pid: 1262
[2020-10-20 06:08:07 +0000] [1268] [INFO] Booting worker with pid: 1268
[2020-10-20 06:08:07 +0000] [1269] [INFO] Booting worker with pid: 1269
[2020-10-20 06:08:08 +0000] [1264] [INFO] Booting worker with pid: 1264
[2020-10-20 06:08:08 +0000] [1265] [INFO] Booting worker with pid: 1265
[2020-10-20 06:08:08 +0000] [1266] [INFO] Booting worker with pid: 1266
[2020-10-20 06:08:08 +0000] [1268] [INFO] Booting worker with pid: 1268
[2020-10-20 06:09:01 +0000] [1285] [CRITICAL] WORKER TIMEOUT (pid:1292)
[2020-10-20 06:09:01 +0000] [1292] [INFO] Worker exiting (pid: 1292)
[2020-10-20 06:09:01 +0000] [1701] [INFO] Booting worker with pid: 1701
[2020-10-20 06:10:36 +0000] [1254] [CRITICAL] WORKER TIMEOUT (pid:1261)
[2020-10-20 06:10:36 +0000] [1261] [INFO] Worker exiting (pid: 1261)
[2020-10-20 06:10:36 +0000] [1305] [INFO] Booting worker with pid: 1305
[2020-10-20 06:11:10 +0000] [1265] [ERROR] Error handling request /?model=ex
Traceback (most recent call last):
  File "/usr/local/lib/python3.6/dist-packages/gunicorn/workers/sync.py", line 134, in handle
    self.handle_request(listener, req, client, addr)
  File "/usr/local/lib/python3.6/dist-packages/gunicorn/workers/sync.py", line 175, in handle_request
    respiter = self.wsgi(environ, resp.start_response)
  File "/usr/local/lib/python3.6/dist-packages/flask/app.py", line 2464, in __call__
    return self.wsgi_app(environ, start_response)
  File "/usr/local/lib/python3.6/dist-packages/flask/app.py", line 2450, in wsgi_app
    response = self.handle_exception(e)
  File "/usr/local/lib/python3.6/dist-packages/flask/app.py", line 1867, in handle_exception
    reraise(exc_type, exc_value, tb)
  File "/usr/local/lib/python3.6/dist-packages/flask/_compat.py", line 39, in reraise
    raise value
  File "/usr/local/lib/python3.6/dist-packages/flask/app.py", line 2447, in wsgi_app
    response = self.full_dispatch_request()
  File "/usr/local/lib/python3.6/dist-packages/flask/app.py", line 1952, in full_dispatch_request
    rv = self.handle_user_exception(e)
  File "/usr/local/lib/python3.6/dist-packages/flask/app.py", line 1821, in handle_user_exception
    reraise(exc_type, exc_value, tb)
  File "/usr/local/lib/python3.6/dist-packages/flask/_compat.py", line 39, in reraise
    raise value
  File "/usr/local/lib/python3.6/dist-packages/flask/app.py", line 1950, in full_dispatch_request
    rv = self.dispatch_request()
  File "/usr/local/lib/python3.6/dist-packages/flask/app.py", line 1936, in dispatch_request
    return self.view_functions[rule.endpoint](**req.view_args)
  File "/root/flask_api_demo/app.py", line 22, in index
    get_model()
  File "/usr/local/lib/python3.6/dist-packages/celery/local.py", line 191, in __call__
    return self._get_current_object()(*a, **kw)
  File "/usr/local/lib/python3.6/dist-packages/celery/app/task.py", line 393, in __call__
    return self.run(*args, **kwargs)
  File "/root/flask_api_demo/app.py", line 31, in get_model
    myUsername = "analy"
ModuleNotFoundError: No module named 'pysftp'
[2020-10-20 06:11:45 +0000] [1285] [INFO] Starting gunicorn 20.0.4
[2020-10-20 06:11:45 +0000] [1285] [INFO] Listening at: http://0.0.0.0:5000 (1285)
[2020-10-20 06:11:45 +0000] [1285] [INFO] Using worker: sync
[2020-10-20 06:11:45 +0000] [1291] [INFO] Booting worker with pid: 1291
[2020-10-20 06:11:45 +0000] [1292] [INFO] Booting worker with pid: 1292
[2020-10-20 06:11:46 +0000] [1295] [INFO] Booting worker with pid: 1295
[2020-10-20 06:11:46 +0000] [1297] [INFO] Booting worker with pid: 1297
[2020-10-20 06:11:46 +0000] [1301] [INFO] Booting worker with pid: 1301
[2020-10-20 06:11:46 +0000] [1302] [INFO] Booting worker with pid: 1302
[2020-10-20 06:12:17 +0000] [1287] [INFO] Starting gunicorn 20.0.4
[2020-10-20 06:12:17 +0000] [1287] [INFO] Listening at: http://0.0.0.0:5000 (1287)
[2020-10-20 06:12:17 +0000] [1287] [INFO] Using worker: sync
[2020-10-20 06:12:17 +0000] [1293] [INFO] Booting worker with pid: 1293
[2020-10-20 06:12:17 +0000] [1294] [INFO] Booting worker with pid: 1294
[2020-10-20 06:12:17 +0000] [1295] [INFO] Booting worker with pid: 1295
[2020-10-20 06:12:17 +0000] [1299] [INFO] Booting worker with pid: 1299
[2020-10-20 06:12:17 +0000] [1300] [INFO] Booting worker with pid: 1300
[2020-10-20 06:12:17 +0000] [1302] [INFO] Booting worker with pid: 1302
[2020-10-20 06:12:24 +0000] [1299] [ERROR] Error handling request /?model=ex
Traceback (most recent call last):
  File "/usr/local/lib/python3.6/dist-packages/gunicorn/workers/sync.py", line 134, in handle
    self.handle_request(listener, req, client, addr)
  File "/usr/local/lib/python3.6/dist-packages/gunicorn/workers/sync.py", line 175, in handle_request
    respiter = self.wsgi(environ, resp.start_response)
  File "/usr/local/lib/python3.6/dist-packages/flask/app.py", line 2464, in __call__
    return self.wsgi_app(environ, start_response)
  File "/usr/local/lib/python3.6/dist-packages/flask/app.py", line 2450, in wsgi_app
    response = self.handle_exception(e)
  File "/usr/local/lib/python3.6/dist-packages/flask/app.py", line 1867, in handle_exception
    reraise(exc_type, exc_value, tb)
  File "/usr/local/lib/python3.6/dist-packages/flask/_compat.py", line 39, in reraise
    raise value
  File "/usr/local/lib/python3.6/dist-packages/flask/app.py", line 2447, in wsgi_app
    response = self.full_dispatch_request()
  File "/usr/local/lib/python3.6/dist-packages/flask/app.py", line 1952, in full_dispatch_request
    rv = self.handle_user_exception(e)
  File "/usr/local/lib/python3.6/dist-packages/flask/app.py", line 1821, in handle_user_exception
    reraise(exc_type, exc_value, tb)
  File "/usr/local/lib/python3.6/dist-packages/flask/_compat.py", line 39, in reraise
    raise value
  File "/usr/local/lib/python3.6/dist-packages/flask/app.py", line 1950, in full_dispatch_request
    rv = self.dispatch_request()
  File "/usr/local/lib/python3.6/dist-packages/flask/app.py", line 1936, in dispatch_request
    return self.view_functions[rule.endpoint](**req.view_args)
  File "/root/flask_api_demo/app.py", line 22, in index
    get_model()
  File "/usr/local/lib/python3.6/dist-packages/celery/local.py", line 191, in __call__
    return self._get_current_object()(*a, **kw)
  File "/usr/local/lib/python3.6/dist-packages/celery/app/task.py", line 393, in __call__
    return self.run(*args, **kwargs)
  File "/root/flask_api_demo/app.py", line 34, in get_model
    with pysftp.Connection(host=myHostname, username=myUsername, password=myPassword) as sftp:
NameError: name 'pysftp' is not defined
[2020-10-20 06:12:55 +0000] [1287] [CRITICAL] WORKER TIMEOUT (pid:1294)
[2020-10-20 06:12:55 +0000] [1287] [CRITICAL] WORKER TIMEOUT (pid:1295)
[2020-10-20 06:12:55 +0000] [1294] [INFO] Worker exiting (pid: 1294)
[2020-10-20 06:12:55 +0000] [1295] [INFO] Worker exiting (pid: 1295)
[2020-10-20 06:12:55 +0000] [1315] [INFO] Booting worker with pid: 1315
[2020-10-20 06:12:55 +0000] [1317] [INFO] Booting worker with pid: 1317
[2020-10-20 06:13:38 +0000] [1300] [INFO] Starting gunicorn 20.0.4
[2020-10-20 06:13:38 +0000] [1300] [INFO] Listening at: http://0.0.0.0:5000 (1300)
[2020-10-20 06:13:38 +0000] [1300] [INFO] Using worker: sync
[2020-10-20 06:13:38 +0000] [1306] [INFO] Booting worker with pid: 1306
[2020-10-20 06:13:38 +0000] [1307] [INFO] Booting worker with pid: 1307
[2020-10-20 06:13:38 +0000] [1309] [INFO] Booting worker with pid: 1309
[2020-10-20 06:13:38 +0000] [1312] [INFO] Booting worker with pid: 1312
[2020-10-20 06:13:38 +0000] [1313] [INFO] Booting worker with pid: 1313
[2020-10-20 06:13:38 +0000] [1317] [INFO] Booting worker with pid: 1317
[2020-10-20 06:13:53 +0000] [1317] [ERROR] Error handling request /?model=ex
Traceback (most recent call last):
  File "/usr/local/lib/python3.6/dist-packages/gunicorn/workers/sync.py", line 134, in handle
    self.handle_request(listener, req, client, addr)
  File "/usr/local/lib/python3.6/dist-packages/gunicorn/workers/sync.py", line 175, in handle_request
    respiter = self.wsgi(environ, resp.start_response)
  File "/usr/local/lib/python3.6/dist-packages/flask/app.py", line 2464, in __call__
    return self.wsgi_app(environ, start_response)
  File "/usr/local/lib/python3.6/dist-packages/flask/app.py", line 2450, in wsgi_app
    response = self.handle_exception(e)
  File "/usr/local/lib/python3.6/dist-packages/flask/app.py", line 1867, in handle_exception
    reraise(exc_type, exc_value, tb)
  File "/usr/local/lib/python3.6/dist-packages/flask/_compat.py", line 39, in reraise
    raise value
  File "/usr/local/lib/python3.6/dist-packages/flask/app.py", line 2447, in wsgi_app
    response = self.full_dispatch_request()
  File "/usr/local/lib/python3.6/dist-packages/flask/app.py", line 1952, in full_dispatch_request
    rv = self.handle_user_exception(e)
  File "/usr/local/lib/python3.6/dist-packages/flask/app.py", line 1821, in handle_user_exception
    reraise(exc_type, exc_value, tb)
  File "/usr/local/lib/python3.6/dist-packages/flask/_compat.py", line 39, in reraise
    raise value
  File "/usr/local/lib/python3.6/dist-packages/flask/app.py", line 1950, in full_dispatch_request
    rv = self.dispatch_request()
  File "/usr/local/lib/python3.6/dist-packages/flask/app.py", line 1936, in dispatch_request
    return self.view_functions[rule.endpoint](**req.view_args)
  File "/root/flask_api_demo/app.py", line 22, in index
    get_model()
  File "/usr/local/lib/python3.6/dist-packages/celery/local.py", line 191, in __call__
    return self._get_current_object()(*a, **kw)
  File "/usr/local/lib/python3.6/dist-packages/celery/app/task.py", line 393, in __call__
    return self.run(*args, **kwargs)
  File "/root/flask_api_demo/app.py", line 34, in get_model
    with pysftp.Connection(host=myHostname, username=myUsername, password=myPassword) as sftp:
NameError: name 'pysftp' is not defined
[2020-10-20 06:13:57 +0000] [1306] [ERROR] Error handling request /?model=ex
Traceback (most recent call last):
  File "/usr/local/lib/python3.6/dist-packages/gunicorn/workers/sync.py", line 134, in handle
    self.handle_request(listener, req, client, addr)
  File "/usr/local/lib/python3.6/dist-packages/gunicorn/workers/sync.py", line 175, in handle_request
    respiter = self.wsgi(environ, resp.start_response)
  File "/usr/local/lib/python3.6/dist-packages/flask/app.py", line 2464, in __call__
    return self.wsgi_app(environ, start_response)
  File "/usr/local/lib/python3.6/dist-packages/flask/app.py", line 2450, in wsgi_app
    response = self.handle_exception(e)
  File "/usr/local/lib/python3.6/dist-packages/flask/app.py", line 1867, in handle_exception
    reraise(exc_type, exc_value, tb)
  File "/usr/local/lib/python3.6/dist-packages/flask/_compat.py", line 39, in reraise
    raise value
  File "/usr/local/lib/python3.6/dist-packages/flask/app.py", line 2447, in wsgi_app
    response = self.full_dispatch_request()
  File "/usr/local/lib/python3.6/dist-packages/flask/app.py", line 1952, in full_dispatch_request
    rv = self.handle_user_exception(e)
  File "/usr/local/lib/python3.6/dist-packages/flask/app.py", line 1821, in handle_user_exception
    reraise(exc_type, exc_value, tb)
  File "/usr/local/lib/python3.6/dist-packages/flask/_compat.py", line 39, in reraise
    raise value
  File "/usr/local/lib/python3.6/dist-packages/flask/app.py", line 1950, in full_dispatch_request
    rv = self.dispatch_request()
  File "/usr/local/lib/python3.6/dist-packages/flask/app.py", line 1936, in dispatch_request
    return self.view_functions[rule.endpoint](**req.view_args)
  File "/root/flask_api_demo/app.py", line 22, in index
    get_model()
  File "/usr/local/lib/python3.6/dist-packages/celery/local.py", line 191, in __call__
    return self._get_current_object()(*a, **kw)
  File "/usr/local/lib/python3.6/dist-packages/celery/app/task.py", line 393, in __call__
    return self.run(*args, **kwargs)
  File "/root/flask_api_demo/app.py", line 34, in get_model
    with pysftp.Connection(host=myHostname, username=myUsername, password=myPassword) as sftp:
NameError: name 'pysftp' is not defined
[2020-10-20 06:14:02 +0000] [1309] [ERROR] Error handling request /?model=ex
Traceback (most recent call last):
  File "/usr/local/lib/python3.6/dist-packages/gunicorn/workers/sync.py", line 134, in handle
    self.handle_request(listener, req, client, addr)
  File "/usr/local/lib/python3.6/dist-packages/gunicorn/workers/sync.py", line 175, in handle_request
    respiter = self.wsgi(environ, resp.start_response)
  File "/usr/local/lib/python3.6/dist-packages/flask/app.py", line 2464, in __call__
    return self.wsgi_app(environ, start_response)
  File "/usr/local/lib/python3.6/dist-packages/flask/app.py", line 2450, in wsgi_app
    response = self.handle_exception(e)
  File "/usr/local/lib/python3.6/dist-packages/flask/app.py", line 1867, in handle_exception
    reraise(exc_type, exc_value, tb)
  File "/usr/local/lib/python3.6/dist-packages/flask/_compat.py", line 39, in reraise
    raise value
  File "/usr/local/lib/python3.6/dist-packages/flask/app.py", line 2447, in wsgi_app
    response = self.full_dispatch_request()
  File "/usr/local/lib/python3.6/dist-packages/flask/app.py", line 1952, in full_dispatch_request
    rv = self.handle_user_exception(e)
  File "/usr/local/lib/python3.6/dist-packages/flask/app.py", line 1821, in handle_user_exception
    reraise(exc_type, exc_value, tb)
  File "/usr/local/lib/python3.6/dist-packages/flask/_compat.py", line 39, in reraise
    raise value
  File "/usr/local/lib/python3.6/dist-packages/flask/app.py", line 1950, in full_dispatch_request
    rv = self.dispatch_request()
  File "/usr/local/lib/python3.6/dist-packages/flask/app.py", line 1936, in dispatch_request
    return self.view_functions[rule.endpoint](**req.view_args)
  File "/root/flask_api_demo/app.py", line 22, in index
    get_model()
  File "/usr/local/lib/python3.6/dist-packages/celery/local.py", line 191, in __call__
    return self._get_current_object()(*a, **kw)
  File "/usr/local/lib/python3.6/dist-packages/celery/app/task.py", line 393, in __call__
    return self.run(*args, **kwargs)
  File "/root/flask_api_demo/app.py", line 34, in get_model
    with pysftp.Connection(host=myHostname, username=myUsername, password=myPassword) as sftp:
NameError: name 'pysftp' is not defined
[2020-10-20 06:14:47 +0000] [1286] [INFO] Starting gunicorn 20.0.4
[2020-10-20 06:14:47 +0000] [1286] [INFO] Listening at: http://0.0.0.0:5000 (1286)
[2020-10-20 06:14:47 +0000] [1286] [INFO] Using worker: sync
[2020-10-20 06:14:47 +0000] [1292] [INFO] Booting worker with pid: 1292
[2020-10-20 06:14:47 +0000] [1293] [INFO] Booting worker with pid: 1293
[2020-10-20 06:14:47 +0000] [1294] [INFO] Booting worker with pid: 1294
[2020-10-20 06:14:47 +0000] [1297] [INFO] Booting worker with pid: 1297
[2020-10-20 06:14:48 +0000] [1299] [INFO] Booting worker with pid: 1299
[2020-10-20 06:14:48 +0000] [1301] [INFO] Booting worker with pid: 1301
[2020-10-20 06:15:22 +0000] [1286] [CRITICAL] WORKER TIMEOUT (pid:1294)
[2020-10-20 06:15:22 +0000] [1294] [INFO] Worker exiting (pid: 1294)
[2020-10-20 06:15:22 +0000] [1332] [INFO] Booting worker with pid: 1332
[2020-10-20 06:15:44 +0000] [1274] [INFO] Starting gunicorn 20.0.4
[2020-10-20 06:15:44 +0000] [1274] [INFO] Listening at: http://0.0.0.0:5000 (1274)
[2020-10-20 06:15:44 +0000] [1274] [INFO] Using worker: sync
[2020-10-20 06:15:44 +0000] [1281] [INFO] Booting worker with pid: 1281
[2020-10-20 06:15:44 +0000] [1282] [INFO] Booting worker with pid: 1282
[2020-10-20 06:15:44 +0000] [1284] [INFO] Booting worker with pid: 1284
[2020-10-20 06:15:44 +0000] [1282] [ERROR] Exception in worker process
Traceback (most recent call last):
  File "/usr/local/lib/python3.6/dist-packages/gunicorn/arbiter.py", line 583, in spawn_worker
    worker.init_process()
  File "/usr/local/lib/python3.6/dist-packages/gunicorn/workers/base.py", line 119, in init_process
    self.load_wsgi()
  File "/usr/local/lib/python3.6/dist-packages/gunicorn/workers/base.py", line 144, in load_wsgi
    self.wsgi = self.app.wsgi()
  File "/usr/local/lib/python3.6/dist-packages/gunicorn/app/base.py", line 67, in wsgi
    self.callable = self.load()
  File "/usr/local/lib/python3.6/dist-packages/gunicorn/app/wsgiapp.py", line 49, in load
    return self.load_wsgiapp()
  File "/usr/local/lib/python3.6/dist-packages/gunicorn/app/wsgiapp.py", line 39, in load_wsgiapp
    return util.import_app(self.app_uri)
  File "/usr/local/lib/python3.6/dist-packages/gunicorn/util.py", line 358, in import_app
    mod = importlib.import_module(module)
  File "/usr/lib/python3.6/importlib/__init__.py", line 126, in import_module
    return _bootstrap._gcd_import(name[level:], package, level)
  File "<frozen importlib._bootstrap>", line 994, in _gcd_import
  File "<frozen importlib._bootstrap>", line 971, in _find_and_load
  File "<frozen importlib._bootstrap>", line 955, in _find_and_load_unlocked
  File "<frozen importlib._bootstrap>", line 665, in _load_unlocked
  File "<frozen importlib._bootstrap_external>", line 678, in exec_module
  File "<frozen importlib._bootstrap>", line 219, in _call_with_frames_removed
  File "/root/flask_api_demo/app.py", line 5, in <module>
    import pysftp
ModuleNotFoundError: No module named 'pysftp'
[2020-10-20 06:15:44 +0000] [1282] [INFO] Worker exiting (pid: 1282)
[2020-10-20 06:15:44 +0000] [1286] [INFO] Booting worker with pid: 1286
[2020-10-20 06:15:44 +0000] [1254] [INFO] Starting gunicorn 20.0.4
[2020-10-20 06:15:44 +0000] [1254] [INFO] Listening at: http://0.0.0.0:5000 (1254)
[2020-10-20 06:15:44 +0000] [1254] [INFO] Using worker: sync
[2020-10-20 06:15:44 +0000] [1261] [INFO] Booting worker with pid: 1261
[2020-10-20 06:15:44 +0000] [1262] [INFO] Booting worker with pid: 1262
[2020-10-20 06:15:44 +0000] [1281] [ERROR] Exception in worker process
Traceback (most recent call last):
  File "/usr/local/lib/python3.6/dist-packages/gunicorn/arbiter.py", line 583, in spawn_worker
    worker.init_process()
  File "/usr/local/lib/python3.6/dist-packages/gunicorn/workers/base.py", line 119, in init_process
    self.load_wsgi()
  File "/usr/local/lib/python3.6/dist-packages/gunicorn/workers/base.py", line 144, in load_wsgi
    self.wsgi = self.app.wsgi()
  File "/usr/local/lib/python3.6/dist-packages/gunicorn/app/base.py", line 67, in wsgi
    self.callable = self.load()
  File "/usr/local/lib/python3.6/dist-packages/gunicorn/app/wsgiapp.py", line 49, in load
    return self.load_wsgiapp()
  File "/usr/local/lib/python3.6/dist-packages/gunicorn/app/wsgiapp.py", line 39, in load_wsgiapp
    return util.import_app(self.app_uri)
  File "/usr/local/lib/python3.6/dist-packages/gunicorn/util.py", line 358, in import_app
    mod = importlib.import_module(module)
  File "/usr/lib/python3.6/importlib/__init__.py", line 126, in import_module
    return _bootstrap._gcd_import(name[level:], package, level)
  File "<frozen importlib._bootstrap>", line 994, in _gcd_import
  File "<frozen importlib._bootstrap>", line 971, in _find_and_load
  File "<frozen importlib._bootstrap>", line 955, in _find_and_load_unlocked
  File "<frozen importlib._bootstrap>", line 665, in _load_unlocked
  File "<frozen importlib._bootstrap_external>", line 678, in exec_module
  File "<frozen importlib._bootstrap>", line 219, in _call_with_frames_removed
  File "/root/flask_api_demo/app.py", line 5, in <module>
    import pysftp
ModuleNotFoundError: No module named 'pysftp'
[2020-10-20 06:15:44 +0000] [1281] [INFO] Worker exiting (pid: 1281)
[2020-10-20 06:15:44 +0000] [1284] [ERROR] Exception in worker process
Traceback (most recent call last):
  File "/usr/local/lib/python3.6/dist-packages/gunicorn/arbiter.py", line 583, in spawn_worker
    worker.init_process()
  File "/usr/local/lib/python3.6/dist-packages/gunicorn/workers/base.py", line 119, in init_process
    self.load_wsgi()
  File "/usr/local/lib/python3.6/dist-packages/gunicorn/workers/base.py", line 144, in load_wsgi
    self.wsgi = self.app.wsgi()
  File "/usr/local/lib/python3.6/dist-packages/gunicorn/app/base.py", line 67, in wsgi
    self.callable = self.load()
  File "/usr/local/lib/python3.6/dist-packages/gunicorn/app/wsgiapp.py", line 49, in load
    return self.load_wsgiapp()
  File "/usr/local/lib/python3.6/dist-packages/gunicorn/app/wsgiapp.py", line 39, in load_wsgiapp
    return util.import_app(self.app_uri)
  File "/usr/local/lib/python3.6/dist-packages/gunicorn/util.py", line 358, in import_app
    mod = importlib.import_module(module)
  File "/usr/lib/python3.6/importlib/__init__.py", line 126, in import_module
    return _bootstrap._gcd_import(name[level:], package, level)
  File "<frozen importlib._bootstrap>", line 994, in _gcd_import
  File "<frozen importlib._bootstrap>", line 971, in _find_and_load
  File "<frozen importlib._bootstrap>", line 955, in _find_and_load_unlocked
  File "<frozen importlib._bootstrap>", line 665, in _load_unlocked
  File "<frozen importlib._bootstrap_external>", line 678, in exec_module
  File "<frozen importlib._bootstrap>", line 219, in _call_with_frames_removed
  File "/root/flask_api_demo/app.py", line 5, in <module>
    import pysftp
ModuleNotFoundError: No module named 'pysftp'
[2020-10-20 06:15:44 +0000] [1284] [INFO] Worker exiting (pid: 1284)
[2020-10-20 06:15:44 +0000] [1264] [INFO] Booting worker with pid: 1264
[2020-10-20 06:15:44 +0000] [1261] [ERROR] Exception in worker process
Traceback (most recent call last):
  File "/usr/local/lib/python3.6/dist-packages/gunicorn/arbiter.py", line 583, in spawn_worker
    worker.init_process()
  File "/usr/local/lib/python3.6/dist-packages/gunicorn/workers/base.py", line 119, in init_process
    self.load_wsgi()
  File "/usr/local/lib/python3.6/dist-packages/gunicorn/workers/base.py", line 144, in load_wsgi
    self.wsgi = self.app.wsgi()
  File "/usr/local/lib/python3.6/dist-packages/gunicorn/app/base.py", line 67, in wsgi
    self.callable = self.load()
  File "/usr/local/lib/python3.6/dist-packages/gunicorn/app/wsgiapp.py", line 49, in load
    return self.load_wsgiapp()
  File "/usr/local/lib/python3.6/dist-packages/gunicorn/app/wsgiapp.py", line 39, in load_wsgiapp
    return util.import_app(self.app_uri)
  File "/usr/local/lib/python3.6/dist-packages/gunicorn/util.py", line 358, in import_app
    mod = importlib.import_module(module)
  File "/usr/lib/python3.6/importlib/__init__.py", line 126, in import_module
    return _bootstrap._gcd_import(name[level:], package, level)
  File "<frozen importlib._bootstrap>", line 994, in _gcd_import
  File "<frozen importlib._bootstrap>", line 971, in _find_and_load
  File "<frozen importlib._bootstrap>", line 955, in _find_and_load_unlocked
  File "<frozen importlib._bootstrap>", line 665, in _load_unlocked
  File "<frozen importlib._bootstrap_external>", line 678, in exec_module
  File "<frozen importlib._bootstrap>", line 219, in _call_with_frames_removed
  File "/root/flask_api_demo/app.py", line 5, in <module>
    import pysftp
ModuleNotFoundError: No module named 'pysftp'
[2020-10-20 06:15:44 +0000] [1261] [INFO] Worker exiting (pid: 1261)
[2020-10-20 06:15:44 +0000] [1286] [ERROR] Exception in worker process
Traceback (most recent call last):
  File "/usr/local/lib/python3.6/dist-packages/gunicorn/arbiter.py", line 583, in spawn_worker
    worker.init_process()
  File "/usr/local/lib/python3.6/dist-packages/gunicorn/workers/base.py", line 119, in init_process
    self.load_wsgi()
  File "/usr/local/lib/python3.6/dist-packages/gunicorn/workers/base.py", line 144, in load_wsgi
    self.wsgi = self.app.wsgi()
  File "/usr/local/lib/python3.6/dist-packages/gunicorn/app/base.py", line 67, in wsgi
    self.callable = self.load()
  File "/usr/local/lib/python3.6/dist-packages/gunicorn/app/wsgiapp.py", line 49, in load
    return self.load_wsgiapp()
  File "/usr/local/lib/python3.6/dist-packages/gunicorn/app/wsgiapp.py", line 39, in load_wsgiapp
    return util.import_app(self.app_uri)
  File "/usr/local/lib/python3.6/dist-packages/gunicorn/util.py", line 358, in import_app
    mod = importlib.import_module(module)
  File "/usr/lib/python3.6/importlib/__init__.py", line 126, in import_module
    return _bootstrap._gcd_import(name[level:], package, level)
  File "<frozen importlib._bootstrap>", line 994, in _gcd_import
  File "<frozen importlib._bootstrap>", line 971, in _find_and_load
  File "<frozen importlib._bootstrap>", line 955, in _find_and_load_unlocked
  File "<frozen importlib._bootstrap>", line 665, in _load_unlocked
  File "<frozen importlib._bootstrap_external>", line 678, in exec_module
  File "<frozen importlib._bootstrap>", line 219, in _call_with_frames_removed
  File "/root/flask_api_demo/app.py", line 5, in <module>
    import pysftp
ModuleNotFoundError: No module named 'pysftp'
[2020-10-20 06:15:44 +0000] [1286] [INFO] Worker exiting (pid: 1286)
[2020-10-20 06:15:44 +0000] [1266] [INFO] Booting worker with pid: 1266
[2020-10-20 06:15:44 +0000] [1262] [ERROR] Exception in worker process
Traceback (most recent call last):
  File "/usr/local/lib/python3.6/dist-packages/gunicorn/arbiter.py", line 583, in spawn_worker
    worker.init_process()
  File "/usr/local/lib/python3.6/dist-packages/gunicorn/workers/base.py", line 119, in init_process
    self.load_wsgi()
  File "/usr/local/lib/python3.6/dist-packages/gunicorn/workers/base.py", line 144, in load_wsgi
    self.wsgi = self.app.wsgi()
  File "/usr/local/lib/python3.6/dist-packages/gunicorn/app/base.py", line 67, in wsgi
    self.callable = self.load()
  File "/usr/local/lib/python3.6/dist-packages/gunicorn/app/wsgiapp.py", line 49, in load
    return self.load_wsgiapp()
  File "/usr/local/lib/python3.6/dist-packages/gunicorn/app/wsgiapp.py", line 39, in load_wsgiapp
    return util.import_app(self.app_uri)
  File "/usr/local/lib/python3.6/dist-packages/gunicorn/util.py", line 358, in import_app
    mod = importlib.import_module(module)
  File "/usr/lib/python3.6/importlib/__init__.py", line 126, in import_module
    return _bootstrap._gcd_import(name[level:], package, level)
  File "<frozen importlib._bootstrap>", line 994, in _gcd_import
  File "<frozen importlib._bootstrap>", line 971, in _find_and_load
  File "<frozen importlib._bootstrap>", line 955, in _find_and_load_unlocked
  File "<frozen importlib._bootstrap>", line 665, in _load_unlocked
  File "<frozen importlib._bootstrap_external>", line 678, in exec_module
  File "<frozen importlib._bootstrap>", line 219, in _call_with_frames_removed
  File "/root/flask_api_demo/app.py", line 5, in <module>
    import pysftp
ModuleNotFoundError: No module named 'pysftp'
[2020-10-20 06:15:44 +0000] [1262] [INFO] Worker exiting (pid: 1262)
[2020-10-20 06:15:45 +0000] [1264] [ERROR] Exception in worker process
Traceback (most recent call last):
  File "/usr/local/lib/python3.6/dist-packages/gunicorn/arbiter.py", line 583, in spawn_worker
    worker.init_process()
  File "/usr/local/lib/python3.6/dist-packages/gunicorn/workers/base.py", line 119, in init_process
    self.load_wsgi()
  File "/usr/local/lib/python3.6/dist-packages/gunicorn/workers/base.py", line 144, in load_wsgi
    self.wsgi = self.app.wsgi()
  File "/usr/local/lib/python3.6/dist-packages/gunicorn/app/base.py", line 67, in wsgi
    self.callable = self.load()
  File "/usr/local/lib/python3.6/dist-packages/gunicorn/app/wsgiapp.py", line 49, in load
    return self.load_wsgiapp()
  File "/usr/local/lib/python3.6/dist-packages/gunicorn/app/wsgiapp.py", line 39, in load_wsgiapp
    return util.import_app(self.app_uri)
  File "/usr/local/lib/python3.6/dist-packages/gunicorn/util.py", line 358, in import_app
    mod = importlib.import_module(module)
  File "/usr/lib/python3.6/importlib/__init__.py", line 126, in import_module
    return _bootstrap._gcd_import(name[level:], package, level)
  File "<frozen importlib._bootstrap>", line 994, in _gcd_import
  File "<frozen importlib._bootstrap>", line 971, in _find_and_load
  File "<frozen importlib._bootstrap>", line 955, in _find_and_load_unlocked
  File "<frozen importlib._bootstrap>", line 665, in _load_unlocked
  File "<frozen importlib._bootstrap_external>", line 678, in exec_module
  File "<frozen importlib._bootstrap>", line 219, in _call_with_frames_removed
  File "/root/flask_api_demo/app.py", line 5, in <module>
    import pysftp
ModuleNotFoundError: No module named 'pysftp'
[2020-10-20 06:15:45 +0000] [1264] [INFO] Worker exiting (pid: 1264)
[2020-10-20 06:15:45 +0000] [1266] [ERROR] Exception in worker process
Traceback (most recent call last):
  File "/usr/local/lib/python3.6/dist-packages/gunicorn/arbiter.py", line 583, in spawn_worker
    worker.init_process()
  File "/usr/local/lib/python3.6/dist-packages/gunicorn/workers/base.py", line 119, in init_process
    self.load_wsgi()
  File "/usr/local/lib/python3.6/dist-packages/gunicorn/workers/base.py", line 144, in load_wsgi
    self.wsgi = self.app.wsgi()
  File "/usr/local/lib/python3.6/dist-packages/gunicorn/app/base.py", line 67, in wsgi
    self.callable = self.load()
  File "/usr/local/lib/python3.6/dist-packages/gunicorn/app/wsgiapp.py", line 49, in load
    return self.load_wsgiapp()
  File "/usr/local/lib/python3.6/dist-packages/gunicorn/app/wsgiapp.py", line 39, in load_wsgiapp
    return util.import_app(self.app_uri)
  File "/usr/local/lib/python3.6/dist-packages/gunicorn/util.py", line 358, in import_app
    mod = importlib.import_module(module)
  File "/usr/lib/python3.6/importlib/__init__.py", line 126, in import_module
    return _bootstrap._gcd_import(name[level:], package, level)
  File "<frozen importlib._bootstrap>", line 994, in _gcd_import
  File "<frozen importlib._bootstrap>", line 971, in _find_and_load
  File "<frozen importlib._bootstrap>", line 955, in _find_and_load_unlocked
  File "<frozen importlib._bootstrap>", line 665, in _load_unlocked
  File "<frozen importlib._bootstrap_external>", line 678, in exec_module
  File "<frozen importlib._bootstrap>", line 219, in _call_with_frames_removed
  File "/root/flask_api_demo/app.py", line 5, in <module>
    import pysftp
ModuleNotFoundError: No module named 'pysftp'
[2020-10-20 06:15:45 +0000] [1266] [INFO] Worker exiting (pid: 1266)
[2020-10-20 06:18:15 +0000] [1254] [INFO] Starting gunicorn 20.0.4
[2020-10-20 06:18:15 +0000] [1254] [INFO] Listening at: http://0.0.0.0:5000 (1254)
[2020-10-20 06:18:15 +0000] [1254] [INFO] Using worker: sync
[2020-10-20 06:18:15 +0000] [1258] [INFO] Booting worker with pid: 1258
[2020-10-20 06:18:15 +0000] [1254] [INFO] Starting gunicorn 20.0.4
[2020-10-20 06:18:15 +0000] [1254] [INFO] Listening at: http://0.0.0.0:5000 (1254)
[2020-10-20 06:18:15 +0000] [1254] [INFO] Using worker: sync
[2020-10-20 06:18:15 +0000] [1261] [INFO] Booting worker with pid: 1261
[2020-10-20 06:18:15 +0000] [1262] [INFO] Booting worker with pid: 1262
[2020-10-20 06:18:16 +0000] [1263] [INFO] Booting worker with pid: 1263
[2020-10-20 06:18:16 +0000] [1264] [INFO] Booting worker with pid: 1264
[2020-10-20 06:18:16 +0000] [1264] [INFO] Booting worker with pid: 1264
[2020-10-20 06:18:16 +0000] [1265] [INFO] Booting worker with pid: 1265
[2020-10-20 06:18:16 +0000] [1265] [INFO] Booting worker with pid: 1265
[2020-10-20 06:18:16 +0000] [1258] [ERROR] Exception in worker process
Traceback (most recent call last):
  File "/usr/local/lib/python3.6/dist-packages/gunicorn/arbiter.py", line 583, in spawn_worker
    worker.init_process()
  File "/usr/local/lib/python3.6/dist-packages/gunicorn/workers/base.py", line 119, in init_process
    self.load_wsgi()
  File "/usr/local/lib/python3.6/dist-packages/gunicorn/workers/base.py", line 144, in load_wsgi
    self.wsgi = self.app.wsgi()
  File "/usr/local/lib/python3.6/dist-packages/gunicorn/app/base.py", line 67, in wsgi
    self.callable = self.load()
  File "/usr/local/lib/python3.6/dist-packages/gunicorn/app/wsgiapp.py", line 49, in load
    return self.load_wsgiapp()
  File "/usr/local/lib/python3.6/dist-packages/gunicorn/app/wsgiapp.py", line 39, in load_wsgiapp
    return util.import_app(self.app_uri)
  File "/usr/local/lib/python3.6/dist-packages/gunicorn/util.py", line 358, in import_app
    mod = importlib.import_module(module)
  File "/usr/lib/python3.6/importlib/__init__.py", line 126, in import_module
    return _bootstrap._gcd_import(name[level:], package, level)
  File "<frozen importlib._bootstrap>", line 994, in _gcd_import
  File "<frozen importlib._bootstrap>", line 971, in _find_and_load
  File "<frozen importlib._bootstrap>", line 955, in _find_and_load_unlocked
  File "<frozen importlib._bootstrap>", line 665, in _load_unlocked
  File "<frozen importlib._bootstrap_external>", line 678, in exec_module
  File "<frozen importlib._bootstrap>", line 219, in _call_with_frames_removed
  File "/root/flask_api_demo/app.py", line 5, in <module>
    import pysftp
ModuleNotFoundError: No module named 'pysftp'
[2020-10-20 06:18:16 +0000] [1258] [INFO] Worker exiting (pid: 1258)
[2020-10-20 06:18:16 +0000] [1267] [INFO] Booting worker with pid: 1267
[2020-10-20 06:18:16 +0000] [1268] [INFO] Booting worker with pid: 1268
[2020-10-20 06:18:16 +0000] [1268] [INFO] Booting worker with pid: 1268
[2020-10-20 06:18:16 +0000] [1269] [INFO] Booting worker with pid: 1269
[2020-10-20 06:18:16 +0000] [1261] [ERROR] Exception in worker process
Traceback (most recent call last):
  File "/usr/local/lib/python3.6/dist-packages/gunicorn/arbiter.py", line 583, in spawn_worker
    worker.init_process()
  File "/usr/local/lib/python3.6/dist-packages/gunicorn/workers/base.py", line 119, in init_process
    self.load_wsgi()
  File "/usr/local/lib/python3.6/dist-packages/gunicorn/workers/base.py", line 144, in load_wsgi
    self.wsgi = self.app.wsgi()
  File "/usr/local/lib/python3.6/dist-packages/gunicorn/app/base.py", line 67, in wsgi
    self.callable = self.load()
  File "/usr/local/lib/python3.6/dist-packages/gunicorn/app/wsgiapp.py", line 49, in load
    return self.load_wsgiapp()
  File "/usr/local/lib/python3.6/dist-packages/gunicorn/app/wsgiapp.py", line 39, in load_wsgiapp
    return util.import_app(self.app_uri)
  File "/usr/local/lib/python3.6/dist-packages/gunicorn/util.py", line 358, in import_app
    mod = importlib.import_module(module)
  File "/usr/lib/python3.6/importlib/__init__.py", line 126, in import_module
    return _bootstrap._gcd_import(name[level:], package, level)
  File "<frozen importlib._bootstrap>", line 994, in _gcd_import
  File "<frozen importlib._bootstrap>", line 971, in _find_and_load
  File "<frozen importlib._bootstrap>", line 955, in _find_and_load_unlocked
  File "<frozen importlib._bootstrap>", line 665, in _load_unlocked
  File "<frozen importlib._bootstrap_external>", line 678, in exec_module
  File "<frozen importlib._bootstrap>", line 219, in _call_with_frames_removed
  File "/root/flask_api_demo/app.py", line 5, in <module>
    import pysftp
ModuleNotFoundError: No module named 'pysftp'
[2020-10-20 06:18:16 +0000] [1261] [INFO] Worker exiting (pid: 1261)
[2020-10-20 06:18:16 +0000] [1264] [ERROR] Exception in worker process
Traceback (most recent call last):
  File "/usr/local/lib/python3.6/dist-packages/gunicorn/arbiter.py", line 583, in spawn_worker
    worker.init_process()
  File "/usr/local/lib/python3.6/dist-packages/gunicorn/workers/base.py", line 119, in init_process
    self.load_wsgi()
  File "/usr/local/lib/python3.6/dist-packages/gunicorn/workers/base.py", line 144, in load_wsgi
    self.wsgi = self.app.wsgi()
  File "/usr/local/lib/python3.6/dist-packages/gunicorn/app/base.py", line 67, in wsgi
    self.callable = self.load()
  File "/usr/local/lib/python3.6/dist-packages/gunicorn/app/wsgiapp.py", line 49, in load
    return self.load_wsgiapp()
  File "/usr/local/lib/python3.6/dist-packages/gunicorn/app/wsgiapp.py", line 39, in load_wsgiapp
    return util.import_app(self.app_uri)
  File "/usr/local/lib/python3.6/dist-packages/gunicorn/util.py", line 358, in import_app
    mod = importlib.import_module(module)
  File "/usr/lib/python3.6/importlib/__init__.py", line 126, in import_module
    return _bootstrap._gcd_import(name[level:], package, level)
  File "<frozen importlib._bootstrap>", line 994, in _gcd_import
  File "<frozen importlib._bootstrap>", line 971, in _find_and_load
  File "<frozen importlib._bootstrap>", line 955, in _find_and_load_unlocked
  File "<frozen importlib._bootstrap>", line 665, in _load_unlocked
  File "<frozen importlib._bootstrap_external>", line 678, in exec_module
  File "<frozen importlib._bootstrap>", line 219, in _call_with_frames_removed
  File "/root/flask_api_demo/app.py", line 5, in <module>
    import pysftp
ModuleNotFoundError: No module named 'pysftp'
[2020-10-20 06:18:16 +0000] [1264] [INFO] Worker exiting (pid: 1264)
[2020-10-20 06:18:16 +0000] [1263] [ERROR] Exception in worker process
Traceback (most recent call last):
  File "/usr/local/lib/python3.6/dist-packages/gunicorn/arbiter.py", line 583, in spawn_worker
    worker.init_process()
  File "/usr/local/lib/python3.6/dist-packages/gunicorn/workers/base.py", line 119, in init_process
    self.load_wsgi()
  File "/usr/local/lib/python3.6/dist-packages/gunicorn/workers/base.py", line 144, in load_wsgi
    self.wsgi = self.app.wsgi()
  File "/usr/local/lib/python3.6/dist-packages/gunicorn/app/base.py", line 67, in wsgi
    self.callable = self.load()
  File "/usr/local/lib/python3.6/dist-packages/gunicorn/app/wsgiapp.py", line 49, in load
    return self.load_wsgiapp()
  File "/usr/local/lib/python3.6/dist-packages/gunicorn/app/wsgiapp.py", line 39, in load_wsgiapp
    return util.import_app(self.app_uri)
  File "/usr/local/lib/python3.6/dist-packages/gunicorn/util.py", line 358, in import_app
    mod = importlib.import_module(module)
  File "/usr/lib/python3.6/importlib/__init__.py", line 126, in import_module
    return _bootstrap._gcd_import(name[level:], package, level)
  File "<frozen importlib._bootstrap>", line 994, in _gcd_import
  File "<frozen importlib._bootstrap>", line 971, in _find_and_load
  File "<frozen importlib._bootstrap>", line 955, in _find_and_load_unlocked
  File "<frozen importlib._bootstrap>", line 665, in _load_unlocked
  File "<frozen importlib._bootstrap_external>", line 678, in exec_module
  File "<frozen importlib._bootstrap>", line 219, in _call_with_frames_removed
  File "/root/flask_api_demo/app.py", line 5, in <module>
    import pysftp
ModuleNotFoundError: No module named 'pysftp'
[2020-10-20 06:18:16 +0000] [1263] [INFO] Worker exiting (pid: 1263)
[2020-10-20 06:18:16 +0000] [1262] [ERROR] Exception in worker process
Traceback (most recent call last):
  File "/usr/local/lib/python3.6/dist-packages/gunicorn/arbiter.py", line 583, in spawn_worker
    worker.init_process()
  File "/usr/local/lib/python3.6/dist-packages/gunicorn/workers/base.py", line 119, in init_process
    self.load_wsgi()
  File "/usr/local/lib/python3.6/dist-packages/gunicorn/workers/base.py", line 144, in load_wsgi
    self.wsgi = self.app.wsgi()
  File "/usr/local/lib/python3.6/dist-packages/gunicorn/app/base.py", line 67, in wsgi
    self.callable = self.load()
  File "/usr/local/lib/python3.6/dist-packages/gunicorn/app/wsgiapp.py", line 49, in load
    return self.load_wsgiapp()
  File "/usr/local/lib/python3.6/dist-packages/gunicorn/app/wsgiapp.py", line 39, in load_wsgiapp
    return util.import_app(self.app_uri)
  File "/usr/local/lib/python3.6/dist-packages/gunicorn/util.py", line 358, in import_app
    mod = importlib.import_module(module)
  File "/usr/lib/python3.6/importlib/__init__.py", line 126, in import_module
    return _bootstrap._gcd_import(name[level:], package, level)
  File "<frozen importlib._bootstrap>", line 994, in _gcd_import
  File "<frozen importlib._bootstrap>", line 971, in _find_and_load
  File "<frozen importlib._bootstrap>", line 955, in _find_and_load_unlocked
  File "<frozen importlib._bootstrap>", line 665, in _load_unlocked
  File "<frozen importlib._bootstrap_external>", line 678, in exec_module
  File "<frozen importlib._bootstrap>", line 219, in _call_with_frames_removed
  File "/root/flask_api_demo/app.py", line 5, in <module>
    import pysftp
ModuleNotFoundError: No module named 'pysftp'
[2020-10-20 06:18:16 +0000] [1262] [INFO] Worker exiting (pid: 1262)
[2020-10-20 06:18:16 +0000] [1267] [ERROR] Exception in worker process
Traceback (most recent call last):
  File "/usr/local/lib/python3.6/dist-packages/gunicorn/arbiter.py", line 583, in spawn_worker
    worker.init_process()
  File "/usr/local/lib/python3.6/dist-packages/gunicorn/workers/base.py", line 119, in init_process
    self.load_wsgi()
  File "/usr/local/lib/python3.6/dist-packages/gunicorn/workers/base.py", line 144, in load_wsgi
    self.wsgi = self.app.wsgi()
  File "/usr/local/lib/python3.6/dist-packages/gunicorn/app/base.py", line 67, in wsgi
    self.callable = self.load()
  File "/usr/local/lib/python3.6/dist-packages/gunicorn/app/wsgiapp.py", line 49, in load
    return self.load_wsgiapp()
  File "/usr/local/lib/python3.6/dist-packages/gunicorn/app/wsgiapp.py", line 39, in load_wsgiapp
    return util.import_app(self.app_uri)
  File "/usr/local/lib/python3.6/dist-packages/gunicorn/util.py", line 358, in import_app
    mod = importlib.import_module(module)
  File "/usr/lib/python3.6/importlib/__init__.py", line 126, in import_module
    return _bootstrap._gcd_import(name[level:], package, level)
  File "<frozen importlib._bootstrap>", line 994, in _gcd_import
  File "<frozen importlib._bootstrap>", line 971, in _find_and_load
  File "<frozen importlib._bootstrap>", line 955, in _find_and_load_unlocked
  File "<frozen importlib._bootstrap>", line 665, in _load_unlocked
  File "<frozen importlib._bootstrap_external>", line 678, in exec_module
  File "<frozen importlib._bootstrap>", line 219, in _call_with_frames_removed
  File "/root/flask_api_demo/app.py", line 5, in <module>
    import pysftp
ModuleNotFoundError: No module named 'pysftp'
[2020-10-20 06:18:16 +0000] [1267] [INFO] Worker exiting (pid: 1267)
[2020-10-20 06:18:16 +0000] [1269] [ERROR] Exception in worker process
Traceback (most recent call last):
  File "/usr/local/lib/python3.6/dist-packages/gunicorn/arbiter.py", line 583, in spawn_worker
    worker.init_process()
  File "/usr/local/lib/python3.6/dist-packages/gunicorn/workers/base.py", line 119, in init_process
    self.load_wsgi()
  File "/usr/local/lib/python3.6/dist-packages/gunicorn/workers/base.py", line 144, in load_wsgi
    self.wsgi = self.app.wsgi()
  File "/usr/local/lib/python3.6/dist-packages/gunicorn/app/base.py", line 67, in wsgi
    self.callable = self.load()
  File "/usr/local/lib/python3.6/dist-packages/gunicorn/app/wsgiapp.py", line 49, in load
    return self.load_wsgiapp()
  File "/usr/local/lib/python3.6/dist-packages/gunicorn/app/wsgiapp.py", line 39, in load_wsgiapp
    return util.import_app(self.app_uri)
  File "/usr/local/lib/python3.6/dist-packages/gunicorn/util.py", line 358, in import_app
    mod = importlib.import_module(module)
  File "/usr/lib/python3.6/importlib/__init__.py", line 126, in import_module
    return _bootstrap._gcd_import(name[level:], package, level)
  File "<frozen importlib._bootstrap>", line 994, in _gcd_import
  File "<frozen importlib._bootstrap>", line 971, in _find_and_load
  File "<frozen importlib._bootstrap>", line 955, in _find_and_load_unlocked
  File "<frozen importlib._bootstrap>", line 665, in _load_unlocked
  File "<frozen importlib._bootstrap_external>", line 678, in exec_module
  File "<frozen importlib._bootstrap>", line 219, in _call_with_frames_removed
  File "/root/flask_api_demo/app.py", line 5, in <module>
    import pysftp
ModuleNotFoundError: No module named 'pysftp'
[2020-10-20 06:18:16 +0000] [1269] [INFO] Worker exiting (pid: 1269)
[2020-10-20 06:18:16 +0000] [1265] [ERROR] Exception in worker process
Traceback (most recent call last):
  File "/usr/local/lib/python3.6/dist-packages/gunicorn/arbiter.py", line 583, in spawn_worker
    worker.init_process()
  File "/usr/local/lib/python3.6/dist-packages/gunicorn/workers/base.py", line 119, in init_process
    self.load_wsgi()
  File "/usr/local/lib/python3.6/dist-packages/gunicorn/workers/base.py", line 144, in load_wsgi
    self.wsgi = self.app.wsgi()
  File "/usr/local/lib/python3.6/dist-packages/gunicorn/app/base.py", line 67, in wsgi
    self.callable = self.load()
  File "/usr/local/lib/python3.6/dist-packages/gunicorn/app/wsgiapp.py", line 49, in load
    return self.load_wsgiapp()
  File "/usr/local/lib/python3.6/dist-packages/gunicorn/app/wsgiapp.py", line 39, in load_wsgiapp
    return util.import_app(self.app_uri)
  File "/usr/local/lib/python3.6/dist-packages/gunicorn/util.py", line 358, in import_app
    mod = importlib.import_module(module)
  File "/usr/lib/python3.6/importlib/__init__.py", line 126, in import_module
    return _bootstrap._gcd_import(name[level:], package, level)
  File "<frozen importlib._bootstrap>", line 994, in _gcd_import
  File "<frozen importlib._bootstrap>", line 971, in _find_and_load
  File "<frozen importlib._bootstrap>", line 955, in _find_and_load_unlocked
  File "<frozen importlib._bootstrap>", line 665, in _load_unlocked
  File "<frozen importlib._bootstrap_external>", line 678, in exec_module
  File "<frozen importlib._bootstrap>", line 219, in _call_with_frames_removed
  File "/root/flask_api_demo/app.py", line 5, in <module>
    import pysftp
ModuleNotFoundError: No module named 'pysftp'
[2020-10-20 06:18:16 +0000] [1265] [INFO] Worker exiting (pid: 1265)
[2020-10-20 06:18:16 +0000] [1265] [ERROR] Exception in worker process
Traceback (most recent call last):
  File "/usr/local/lib/python3.6/dist-packages/gunicorn/arbiter.py", line 583, in spawn_worker
    worker.init_process()
  File "/usr/local/lib/python3.6/dist-packages/gunicorn/workers/base.py", line 119, in init_process
    self.load_wsgi()
  File "/usr/local/lib/python3.6/dist-packages/gunicorn/workers/base.py", line 144, in load_wsgi
    self.wsgi = self.app.wsgi()
  File "/usr/local/lib/python3.6/dist-packages/gunicorn/app/base.py", line 67, in wsgi
    self.callable = self.load()
  File "/usr/local/lib/python3.6/dist-packages/gunicorn/app/wsgiapp.py", line 49, in load
    return self.load_wsgiapp()
  File "/usr/local/lib/python3.6/dist-packages/gunicorn/app/wsgiapp.py", line 39, in load_wsgiapp
    return util.import_app(self.app_uri)
  File "/usr/local/lib/python3.6/dist-packages/gunicorn/util.py", line 358, in import_app
    mod = importlib.import_module(module)
  File "/usr/lib/python3.6/importlib/__init__.py", line 126, in import_module
    return _bootstrap._gcd_import(name[level:], package, level)
  File "<frozen importlib._bootstrap>", line 994, in _gcd_import
  File "<frozen importlib._bootstrap>", line 971, in _find_and_load
  File "<frozen importlib._bootstrap>", line 955, in _find_and_load_unlocked
  File "<frozen importlib._bootstrap>", line 665, in _load_unlocked
  File "<frozen importlib._bootstrap_external>", line 678, in exec_module
  File "<frozen importlib._bootstrap>", line 219, in _call_with_frames_removed
  File "/root/flask_api_demo/app.py", line 5, in <module>
    import pysftp
ModuleNotFoundError: No module named 'pysftp'
[2020-10-20 06:18:16 +0000] [1265] [INFO] Worker exiting (pid: 1265)
[2020-10-20 06:18:16 +0000] [1268] [ERROR] Exception in worker process
Traceback (most recent call last):
  File "/usr/local/lib/python3.6/dist-packages/gunicorn/arbiter.py", line 583, in spawn_worker
    worker.init_process()
  File "/usr/local/lib/python3.6/dist-packages/gunicorn/workers/base.py", line 119, in init_process
    self.load_wsgi()
  File "/usr/local/lib/python3.6/dist-packages/gunicorn/workers/base.py", line 144, in load_wsgi
    self.wsgi = self.app.wsgi()
  File "/usr/local/lib/python3.6/dist-packages/gunicorn/app/base.py", line 67, in wsgi
    self.callable = self.load()
  File "/usr/local/lib/python3.6/dist-packages/gunicorn/app/wsgiapp.py", line 49, in load
    return self.load_wsgiapp()
  File "/usr/local/lib/python3.6/dist-packages/gunicorn/app/wsgiapp.py", line 39, in load_wsgiapp
    return util.import_app(self.app_uri)
  File "/usr/local/lib/python3.6/dist-packages/gunicorn/util.py", line 358, in import_app
    mod = importlib.import_module(module)
  File "/usr/lib/python3.6/importlib/__init__.py", line 126, in import_module
    return _bootstrap._gcd_import(name[level:], package, level)
  File "<frozen importlib._bootstrap>", line 994, in _gcd_import
  File "<frozen importlib._bootstrap>", line 971, in _find_and_load
  File "<frozen importlib._bootstrap>", line 955, in _find_and_load_unlocked
  File "<frozen importlib._bootstrap>", line 665, in _load_unlocked
  File "<frozen importlib._bootstrap_external>", line 678, in exec_module
  File "<frozen importlib._bootstrap>", line 219, in _call_with_frames_removed
  File "/root/flask_api_demo/app.py", line 5, in <module>
    import pysftp
ModuleNotFoundError: No module named 'pysftp'
[2020-10-20 06:18:16 +0000] [1264] [ERROR] Exception in worker process
Traceback (most recent call last):
  File "/usr/local/lib/python3.6/dist-packages/gunicorn/arbiter.py", line 583, in spawn_worker
    worker.init_process()
  File "/usr/local/lib/python3.6/dist-packages/gunicorn/workers/base.py", line 119, in init_process
    self.load_wsgi()
  File "/usr/local/lib/python3.6/dist-packages/gunicorn/workers/base.py", line 144, in load_wsgi
    self.wsgi = self.app.wsgi()
  File "/usr/local/lib/python3.6/dist-packages/gunicorn/app/base.py", line 67, in wsgi
    self.callable = self.load()
  File "/usr/local/lib/python3.6/dist-packages/gunicorn/app/wsgiapp.py", line 49, in load
    return self.load_wsgiapp()
  File "/usr/local/lib/python3.6/dist-packages/gunicorn/app/wsgiapp.py", line 39, in load_wsgiapp
    return util.import_app(self.app_uri)
  File "/usr/local/lib/python3.6/dist-packages/gunicorn/util.py", line 358, in import_app
    mod = importlib.import_module(module)
  File "/usr/lib/python3.6/importlib/__init__.py", line 126, in import_module
    return _bootstrap._gcd_import(name[level:], package, level)
  File "<frozen importlib._bootstrap>", line 994, in _gcd_import
  File "<frozen importlib._bootstrap>", line 971, in _find_and_load
  File "<frozen importlib._bootstrap>", line 955, in _find_and_load_unlocked
  File "<frozen importlib._bootstrap>", line 665, in _load_unlocked
  File "<frozen importlib._bootstrap_external>", line 678, in exec_module
  File "<frozen importlib._bootstrap>", line 219, in _call_with_frames_removed
  File "/root/flask_api_demo/app.py", line 5, in <module>
    import pysftp
ModuleNotFoundError: No module named 'pysftp'
[2020-10-20 06:18:16 +0000] [1268] [INFO] Worker exiting (pid: 1268)
[2020-10-20 06:18:16 +0000] [1264] [INFO] Worker exiting (pid: 1264)
[2020-10-20 06:18:16 +0000] [1268] [ERROR] Exception in worker process
Traceback (most recent call last):
  File "/usr/local/lib/python3.6/dist-packages/gunicorn/arbiter.py", line 583, in spawn_worker
    worker.init_process()
  File "/usr/local/lib/python3.6/dist-packages/gunicorn/workers/base.py", line 119, in init_process
    self.load_wsgi()
  File "/usr/local/lib/python3.6/dist-packages/gunicorn/workers/base.py", line 144, in load_wsgi
    self.wsgi = self.app.wsgi()
  File "/usr/local/lib/python3.6/dist-packages/gunicorn/app/base.py", line 67, in wsgi
    self.callable = self.load()
  File "/usr/local/lib/python3.6/dist-packages/gunicorn/app/wsgiapp.py", line 49, in load
    return self.load_wsgiapp()
  File "/usr/local/lib/python3.6/dist-packages/gunicorn/app/wsgiapp.py", line 39, in load_wsgiapp
    return util.import_app(self.app_uri)
  File "/usr/local/lib/python3.6/dist-packages/gunicorn/util.py", line 358, in import_app
    mod = importlib.import_module(module)
  File "/usr/lib/python3.6/importlib/__init__.py", line 126, in import_module
    return _bootstrap._gcd_import(name[level:], package, level)
  File "<frozen importlib._bootstrap>", line 994, in _gcd_import
  File "<frozen importlib._bootstrap>", line 971, in _find_and_load
  File "<frozen importlib._bootstrap>", line 955, in _find_and_load_unlocked
  File "<frozen importlib._bootstrap>", line 665, in _load_unlocked
  File "<frozen importlib._bootstrap_external>", line 678, in exec_module
  File "<frozen importlib._bootstrap>", line 219, in _call_with_frames_removed
  File "/root/flask_api_demo/app.py", line 5, in <module>
    import pysftp
ModuleNotFoundError: No module named 'pysftp'
[2020-10-20 06:18:16 +0000] [1268] [INFO] Worker exiting (pid: 1268)
[2020-10-20 06:19:58 +0000] [1254] [INFO] Starting gunicorn 20.0.4
[2020-10-20 06:19:58 +0000] [1254] [INFO] Listening at: http://0.0.0.0:5000 (1254)
[2020-10-20 06:19:58 +0000] [1254] [INFO] Using worker: sync
[2020-10-20 06:19:58 +0000] [1261] [INFO] Booting worker with pid: 1261
[2020-10-20 06:19:58 +0000] [1262] [INFO] Booting worker with pid: 1262
[2020-10-20 06:19:58 +0000] [1263] [INFO] Booting worker with pid: 1263
[2020-10-20 06:19:58 +0000] [1265] [INFO] Booting worker with pid: 1265
[2020-10-20 06:19:58 +0000] [1254] [INFO] Starting gunicorn 20.0.4
[2020-10-20 06:19:58 +0000] [1254] [INFO] Listening at: http://0.0.0.0:5000 (1254)
[2020-10-20 06:19:58 +0000] [1254] [INFO] Using worker: sync
[2020-10-20 06:19:58 +0000] [1261] [INFO] Booting worker with pid: 1261
[2020-10-20 06:19:58 +0000] [1261] [ERROR] Exception in worker process
Traceback (most recent call last):
  File "/usr/local/lib/python3.6/dist-packages/gunicorn/arbiter.py", line 583, in spawn_worker
    worker.init_process()
  File "/usr/local/lib/python3.6/dist-packages/gunicorn/workers/base.py", line 119, in init_process
    self.load_wsgi()
  File "/usr/local/lib/python3.6/dist-packages/gunicorn/workers/base.py", line 144, in load_wsgi
    self.wsgi = self.app.wsgi()
  File "/usr/local/lib/python3.6/dist-packages/gunicorn/app/base.py", line 67, in wsgi
    self.callable = self.load()
  File "/usr/local/lib/python3.6/dist-packages/gunicorn/app/wsgiapp.py", line 49, in load
    return self.load_wsgiapp()
  File "/usr/local/lib/python3.6/dist-packages/gunicorn/app/wsgiapp.py", line 39, in load_wsgiapp
    return util.import_app(self.app_uri)
  File "/usr/local/lib/python3.6/dist-packages/gunicorn/util.py", line 358, in import_app
    mod = importlib.import_module(module)
  File "/usr/lib/python3.6/importlib/__init__.py", line 126, in import_module
    return _bootstrap._gcd_import(name[level:], package, level)
  File "<frozen importlib._bootstrap>", line 994, in _gcd_import
  File "<frozen importlib._bootstrap>", line 971, in _find_and_load
  File "<frozen importlib._bootstrap>", line 955, in _find_and_load_unlocked
  File "<frozen importlib._bootstrap>", line 665, in _load_unlocked
  File "<frozen importlib._bootstrap_external>", line 678, in exec_module
  File "<frozen importlib._bootstrap>", line 219, in _call_with_frames_removed
  File "/root/flask_api_demo/app.py", line 5, in <module>
    import pysftp
ModuleNotFoundError: No module named 'pysftp'
[2020-10-20 06:19:58 +0000] [1261] [INFO] Worker exiting (pid: 1261)
[2020-10-20 06:19:58 +0000] [1267] [INFO] Booting worker with pid: 1267
[2020-10-20 06:19:58 +0000] [1262] [INFO] Booting worker with pid: 1262
[2020-10-20 06:19:58 +0000] [1263] [INFO] Booting worker with pid: 1263
[2020-10-20 06:19:58 +0000] [1264] [INFO] Booting worker with pid: 1264
[2020-10-20 06:19:59 +0000] [1262] [ERROR] Exception in worker process
Traceback (most recent call last):
  File "/usr/local/lib/python3.6/dist-packages/gunicorn/arbiter.py", line 583, in spawn_worker
    worker.init_process()
  File "/usr/local/lib/python3.6/dist-packages/gunicorn/workers/base.py", line 119, in init_process
    self.load_wsgi()
  File "/usr/local/lib/python3.6/dist-packages/gunicorn/workers/base.py", line 144, in load_wsgi
    self.wsgi = self.app.wsgi()
  File "/usr/local/lib/python3.6/dist-packages/gunicorn/app/base.py", line 67, in wsgi
    self.callable = self.load()
  File "/usr/local/lib/python3.6/dist-packages/gunicorn/app/wsgiapp.py", line 49, in load
    return self.load_wsgiapp()
  File "/usr/local/lib/python3.6/dist-packages/gunicorn/app/wsgiapp.py", line 39, in load_wsgiapp
    return util.import_app(self.app_uri)
  File "/usr/local/lib/python3.6/dist-packages/gunicorn/util.py", line 358, in import_app
    mod = importlib.import_module(module)
  File "/usr/lib/python3.6/importlib/__init__.py", line 126, in import_module
    return _bootstrap._gcd_import(name[level:], package, level)
  File "<frozen importlib._bootstrap>", line 994, in _gcd_import
  File "<frozen importlib._bootstrap>", line 971, in _find_and_load
  File "<frozen importlib._bootstrap>", line 955, in _find_and_load_unlocked
  File "<frozen importlib._bootstrap>", line 665, in _load_unlocked
  File "<frozen importlib._bootstrap_external>", line 678, in exec_module
  File "<frozen importlib._bootstrap>", line 219, in _call_with_frames_removed
  File "/root/flask_api_demo/app.py", line 5, in <module>
    import pysftp
ModuleNotFoundError: No module named 'pysftp'
[2020-10-20 06:19:59 +0000] [1262] [INFO] Worker exiting (pid: 1262)
[2020-10-20 06:19:59 +0000] [1267] [INFO] Booting worker with pid: 1267
[2020-10-20 06:19:59 +0000] [1263] [ERROR] Exception in worker process
Traceback (most recent call last):
  File "/usr/local/lib/python3.6/dist-packages/gunicorn/arbiter.py", line 583, in spawn_worker
    worker.init_process()
  File "/usr/local/lib/python3.6/dist-packages/gunicorn/workers/base.py", line 119, in init_process
    self.load_wsgi()
  File "/usr/local/lib/python3.6/dist-packages/gunicorn/workers/base.py", line 144, in load_wsgi
    self.wsgi = self.app.wsgi()
  File "/usr/local/lib/python3.6/dist-packages/gunicorn/app/base.py", line 67, in wsgi
    self.callable = self.load()
  File "/usr/local/lib/python3.6/dist-packages/gunicorn/app/wsgiapp.py", line 49, in load
    return self.load_wsgiapp()
  File "/usr/local/lib/python3.6/dist-packages/gunicorn/app/wsgiapp.py", line 39, in load_wsgiapp
    return util.import_app(self.app_uri)
  File "/usr/local/lib/python3.6/dist-packages/gunicorn/util.py", line 358, in import_app
    mod = importlib.import_module(module)
  File "/usr/lib/python3.6/importlib/__init__.py", line 126, in import_module
    return _bootstrap._gcd_import(name[level:], package, level)
  File "<frozen importlib._bootstrap>", line 994, in _gcd_import
  File "<frozen importlib._bootstrap>", line 971, in _find_and_load
  File "<frozen importlib._bootstrap>", line 955, in _find_and_load_unlocked
  File "<frozen importlib._bootstrap>", line 665, in _load_unlocked
  File "<frozen importlib._bootstrap_external>", line 678, in exec_module
  File "<frozen importlib._bootstrap>", line 219, in _call_with_frames_removed
  File "/root/flask_api_demo/app.py", line 5, in <module>
    import pysftp
ModuleNotFoundError: No module named 'pysftp'
[2020-10-20 06:19:59 +0000] [1263] [INFO] Worker exiting (pid: 1263)
[2020-10-20 06:19:59 +0000] [1268] [INFO] Booting worker with pid: 1268
[2020-10-20 06:19:59 +0000] [1265] [ERROR] Exception in worker process
Traceback (most recent call last):
  File "/usr/local/lib/python3.6/dist-packages/gunicorn/arbiter.py", line 583, in spawn_worker
    worker.init_process()
  File "/usr/local/lib/python3.6/dist-packages/gunicorn/workers/base.py", line 119, in init_process
    self.load_wsgi()
  File "/usr/local/lib/python3.6/dist-packages/gunicorn/workers/base.py", line 144, in load_wsgi
    self.wsgi = self.app.wsgi()
  File "/usr/local/lib/python3.6/dist-packages/gunicorn/app/base.py", line 67, in wsgi
    self.callable = self.load()
  File "/usr/local/lib/python3.6/dist-packages/gunicorn/app/wsgiapp.py", line 49, in load
    return self.load_wsgiapp()
  File "/usr/local/lib/python3.6/dist-packages/gunicorn/app/wsgiapp.py", line 39, in load_wsgiapp
    return util.import_app(self.app_uri)
  File "/usr/local/lib/python3.6/dist-packages/gunicorn/util.py", line 358, in import_app
    mod = importlib.import_module(module)
  File "/usr/lib/python3.6/importlib/__init__.py", line 126, in import_module
    return _bootstrap._gcd_import(name[level:], package, level)
  File "<frozen importlib._bootstrap>", line 994, in _gcd_import
  File "<frozen importlib._bootstrap>", line 971, in _find_and_load
  File "<frozen importlib._bootstrap>", line 955, in _find_and_load_unlocked
  File "<frozen importlib._bootstrap>", line 665, in _load_unlocked
  File "<frozen importlib._bootstrap_external>", line 678, in exec_module
  File "<frozen importlib._bootstrap>", line 219, in _call_with_frames_removed
  File "/root/flask_api_demo/app.py", line 5, in <module>
    import pysftp
ModuleNotFoundError: No module named 'pysftp'
[2020-10-20 06:19:59 +0000] [1265] [INFO] Worker exiting (pid: 1265)
[2020-10-20 06:19:59 +0000] [1267] [ERROR] Exception in worker process
Traceback (most recent call last):
  File "/usr/local/lib/python3.6/dist-packages/gunicorn/arbiter.py", line 583, in spawn_worker
    worker.init_process()
  File "/usr/local/lib/python3.6/dist-packages/gunicorn/workers/base.py", line 119, in init_process
    self.load_wsgi()
  File "/usr/local/lib/python3.6/dist-packages/gunicorn/workers/base.py", line 144, in load_wsgi
    self.wsgi = self.app.wsgi()
  File "/usr/local/lib/python3.6/dist-packages/gunicorn/app/base.py", line 67, in wsgi
    self.callable = self.load()
  File "/usr/local/lib/python3.6/dist-packages/gunicorn/app/wsgiapp.py", line 49, in load
    return self.load_wsgiapp()
  File "/usr/local/lib/python3.6/dist-packages/gunicorn/app/wsgiapp.py", line 39, in load_wsgiapp
    return util.import_app(self.app_uri)
  File "/usr/local/lib/python3.6/dist-packages/gunicorn/util.py", line 358, in import_app
    mod = importlib.import_module(module)
  File "/usr/lib/python3.6/importlib/__init__.py", line 126, in import_module
    return _bootstrap._gcd_import(name[level:], package, level)
  File "<frozen importlib._bootstrap>", line 994, in _gcd_import
  File "<frozen importlib._bootstrap>", line 971, in _find_and_load
  File "<frozen importlib._bootstrap>", line 955, in _find_and_load_unlocked
  File "<frozen importlib._bootstrap>", line 665, in _load_unlocked
  File "<frozen importlib._bootstrap_external>", line 678, in exec_module
  File "<frozen importlib._bootstrap>", line 219, in _call_with_frames_removed
  File "/root/flask_api_demo/app.py", line 5, in <module>
    import pysftp
ModuleNotFoundError: No module named 'pysftp'
[2020-10-20 06:19:59 +0000] [1267] [INFO] Worker exiting (pid: 1267)
[2020-10-20 06:19:59 +0000] [1262] [ERROR] Exception in worker process
Traceback (most recent call last):
  File "/usr/local/lib/python3.6/dist-packages/gunicorn/arbiter.py", line 583, in spawn_worker
    worker.init_process()
  File "/usr/local/lib/python3.6/dist-packages/gunicorn/workers/base.py", line 119, in init_process
    self.load_wsgi()
  File "/usr/local/lib/python3.6/dist-packages/gunicorn/workers/base.py", line 144, in load_wsgi
    self.wsgi = self.app.wsgi()
  File "/usr/local/lib/python3.6/dist-packages/gunicorn/app/base.py", line 67, in wsgi
    self.callable = self.load()
  File "/usr/local/lib/python3.6/dist-packages/gunicorn/app/wsgiapp.py", line 49, in load
    return self.load_wsgiapp()
  File "/usr/local/lib/python3.6/dist-packages/gunicorn/app/wsgiapp.py", line 39, in load_wsgiapp
    return util.import_app(self.app_uri)
  File "/usr/local/lib/python3.6/dist-packages/gunicorn/util.py", line 358, in import_app
    mod = importlib.import_module(module)
  File "/usr/lib/python3.6/importlib/__init__.py", line 126, in import_module
    return _bootstrap._gcd_import(name[level:], package, level)
  File "<frozen importlib._bootstrap>", line 994, in _gcd_import
  File "<frozen importlib._bootstrap>", line 971, in _find_and_load
  File "<frozen importlib._bootstrap>", line 955, in _find_and_load_unlocked
  File "<frozen importlib._bootstrap>", line 665, in _load_unlocked
  File "<frozen importlib._bootstrap_external>", line 678, in exec_module
  File "<frozen importlib._bootstrap>", line 219, in _call_with_frames_removed
  File "/root/flask_api_demo/app.py", line 5, in <module>
    import pysftp
ModuleNotFoundError: No module named 'pysftp'
[2020-10-20 06:19:59 +0000] [1262] [INFO] Worker exiting (pid: 1262)
[2020-10-20 06:19:59 +0000] [1261] [ERROR] Exception in worker process
Traceback (most recent call last):
  File "/usr/local/lib/python3.6/dist-packages/gunicorn/arbiter.py", line 583, in spawn_worker
    worker.init_process()
  File "/usr/local/lib/python3.6/dist-packages/gunicorn/workers/base.py", line 119, in init_process
    self.load_wsgi()
  File "/usr/local/lib/python3.6/dist-packages/gunicorn/workers/base.py", line 144, in load_wsgi
    self.wsgi = self.app.wsgi()
  File "/usr/local/lib/python3.6/dist-packages/gunicorn/app/base.py", line 67, in wsgi
    self.callable = self.load()
  File "/usr/local/lib/python3.6/dist-packages/gunicorn/app/wsgiapp.py", line 49, in load
    return self.load_wsgiapp()
  File "/usr/local/lib/python3.6/dist-packages/gunicorn/app/wsgiapp.py", line 39, in load_wsgiapp
    return util.import_app(self.app_uri)
  File "/usr/local/lib/python3.6/dist-packages/gunicorn/util.py", line 358, in import_app
    mod = importlib.import_module(module)
  File "/usr/lib/python3.6/importlib/__init__.py", line 126, in import_module
    return _bootstrap._gcd_import(name[level:], package, level)
  File "<frozen importlib._bootstrap>", line 994, in _gcd_import
  File "<frozen importlib._bootstrap>", line 971, in _find_and_load
  File "<frozen importlib._bootstrap>", line 955, in _find_and_load_unlocked
  File "<frozen importlib._bootstrap>", line 665, in _load_unlocked
  File "<frozen importlib._bootstrap_external>", line 678, in exec_module
  File "<frozen importlib._bootstrap>", line 219, in _call_with_frames_removed
  File "/root/flask_api_demo/app.py", line 5, in <module>
    import pysftp
ModuleNotFoundError: No module named 'pysftp'
[2020-10-20 06:19:59 +0000] [1261] [INFO] Worker exiting (pid: 1261)
[2020-10-20 06:19:59 +0000] [1267] [ERROR] Exception in worker process
Traceback (most recent call last):
  File "/usr/local/lib/python3.6/dist-packages/gunicorn/arbiter.py", line 583, in spawn_worker
    worker.init_process()
  File "/usr/local/lib/python3.6/dist-packages/gunicorn/workers/base.py", line 119, in init_process
    self.load_wsgi()
  File "/usr/local/lib/python3.6/dist-packages/gunicorn/workers/base.py", line 144, in load_wsgi
    self.wsgi = self.app.wsgi()
  File "/usr/local/lib/python3.6/dist-packages/gunicorn/app/base.py", line 67, in wsgi
    self.callable = self.load()
  File "/usr/local/lib/python3.6/dist-packages/gunicorn/app/wsgiapp.py", line 49, in load
    return self.load_wsgiapp()
  File "/usr/local/lib/python3.6/dist-packages/gunicorn/app/wsgiapp.py", line 39, in load_wsgiapp
    return util.import_app(self.app_uri)
  File "/usr/local/lib/python3.6/dist-packages/gunicorn/util.py", line 358, in import_app
    mod = importlib.import_module(module)
  File "/usr/lib/python3.6/importlib/__init__.py", line 126, in import_module
    return _bootstrap._gcd_import(name[level:], package, level)
  File "<frozen importlib._bootstrap>", line 994, in _gcd_import
  File "<frozen importlib._bootstrap>", line 971, in _find_and_load
  File "<frozen importlib._bootstrap>", line 955, in _find_and_load_unlocked
  File "<frozen importlib._bootstrap>", line 665, in _load_unlocked
  File "<frozen importlib._bootstrap_external>", line 678, in exec_module
  File "<frozen importlib._bootstrap>", line 219, in _call_with_frames_removed
  File "/root/flask_api_demo/app.py", line 5, in <module>
    import pysftp
ModuleNotFoundError: No module named 'pysftp'
[2020-10-20 06:19:59 +0000] [1267] [INFO] Worker exiting (pid: 1267)
[2020-10-20 06:19:59 +0000] [1263] [ERROR] Exception in worker process
Traceback (most recent call last):
  File "/usr/local/lib/python3.6/dist-packages/gunicorn/arbiter.py", line 583, in spawn_worker
    worker.init_process()
  File "/usr/local/lib/python3.6/dist-packages/gunicorn/workers/base.py", line 119, in init_process
    self.load_wsgi()
  File "/usr/local/lib/python3.6/dist-packages/gunicorn/workers/base.py", line 144, in load_wsgi
    self.wsgi = self.app.wsgi()
  File "/usr/local/lib/python3.6/dist-packages/gunicorn/app/base.py", line 67, in wsgi
    self.callable = self.load()
  File "/usr/local/lib/python3.6/dist-packages/gunicorn/app/wsgiapp.py", line 49, in load
    return self.load_wsgiapp()
  File "/usr/local/lib/python3.6/dist-packages/gunicorn/app/wsgiapp.py", line 39, in load_wsgiapp
    return util.import_app(self.app_uri)
  File "/usr/local/lib/python3.6/dist-packages/gunicorn/util.py", line 358, in import_app
    mod = importlib.import_module(module)
  File "/usr/lib/python3.6/importlib/__init__.py", line 126, in import_module
    return _bootstrap._gcd_import(name[level:], package, level)
  File "<frozen importlib._bootstrap>", line 994, in _gcd_import
  File "<frozen importlib._bootstrap>", line 971, in _find_and_load
  File "<frozen importlib._bootstrap>", line 955, in _find_and_load_unlocked
  File "<frozen importlib._bootstrap>", line 665, in _load_unlocked
  File "<frozen importlib._bootstrap_external>", line 678, in exec_module
  File "<frozen importlib._bootstrap>", line 219, in _call_with_frames_removed
  File "/root/flask_api_demo/app.py", line 5, in <module>
    import pysftp
ModuleNotFoundError: No module named 'pysftp'
[2020-10-20 06:19:59 +0000] [1263] [INFO] Worker exiting (pid: 1263)
[2020-10-20 06:19:59 +0000] [1264] [ERROR] Exception in worker process
Traceback (most recent call last):
  File "/usr/local/lib/python3.6/dist-packages/gunicorn/arbiter.py", line 583, in spawn_worker
    worker.init_process()
  File "/usr/local/lib/python3.6/dist-packages/gunicorn/workers/base.py", line 119, in init_process
    self.load_wsgi()
  File "/usr/local/lib/python3.6/dist-packages/gunicorn/workers/base.py", line 144, in load_wsgi
    self.wsgi = self.app.wsgi()
  File "/usr/local/lib/python3.6/dist-packages/gunicorn/app/base.py", line 67, in wsgi
    self.callable = self.load()
  File "/usr/local/lib/python3.6/dist-packages/gunicorn/app/wsgiapp.py", line 49, in load
    return self.load_wsgiapp()
  File "/usr/local/lib/python3.6/dist-packages/gunicorn/app/wsgiapp.py", line 39, in load_wsgiapp
    return util.import_app(self.app_uri)
  File "/usr/local/lib/python3.6/dist-packages/gunicorn/util.py", line 358, in import_app
    mod = importlib.import_module(module)
  File "/usr/lib/python3.6/importlib/__init__.py", line 126, in import_module
    return _bootstrap._gcd_import(name[level:], package, level)
  File "<frozen importlib._bootstrap>", line 994, in _gcd_import
  File "<frozen importlib._bootstrap>", line 971, in _find_and_load
  File "<frozen importlib._bootstrap>", line 955, in _find_and_load_unlocked
  File "<frozen importlib._bootstrap>", line 665, in _load_unlocked
  File "<frozen importlib._bootstrap_external>", line 678, in exec_module
  File "<frozen importlib._bootstrap>", line 219, in _call_with_frames_removed
  File "/root/flask_api_demo/app.py", line 5, in <module>
    import pysftp
ModuleNotFoundError: No module named 'pysftp'
[2020-10-20 06:19:59 +0000] [1264] [INFO] Worker exiting (pid: 1264)
[2020-10-20 06:19:59 +0000] [1268] [ERROR] Exception in worker process
Traceback (most recent call last):
  File "/usr/local/lib/python3.6/dist-packages/gunicorn/arbiter.py", line 583, in spawn_worker
    worker.init_process()
  File "/usr/local/lib/python3.6/dist-packages/gunicorn/workers/base.py", line 119, in init_process
    self.load_wsgi()
  File "/usr/local/lib/python3.6/dist-packages/gunicorn/workers/base.py", line 144, in load_wsgi
    self.wsgi = self.app.wsgi()
  File "/usr/local/lib/python3.6/dist-packages/gunicorn/app/base.py", line 67, in wsgi
    self.callable = self.load()
  File "/usr/local/lib/python3.6/dist-packages/gunicorn/app/wsgiapp.py", line 49, in load
    return self.load_wsgiapp()
  File "/usr/local/lib/python3.6/dist-packages/gunicorn/app/wsgiapp.py", line 39, in load_wsgiapp
    return util.import_app(self.app_uri)
  File "/usr/local/lib/python3.6/dist-packages/gunicorn/util.py", line 358, in import_app
    mod = importlib.import_module(module)
  File "/usr/lib/python3.6/importlib/__init__.py", line 126, in import_module
    return _bootstrap._gcd_import(name[level:], package, level)
  File "<frozen importlib._bootstrap>", line 994, in _gcd_import
  File "<frozen importlib._bootstrap>", line 971, in _find_and_load
  File "<frozen importlib._bootstrap>", line 955, in _find_and_load_unlocked
  File "<frozen importlib._bootstrap>", line 665, in _load_unlocked
  File "<frozen importlib._bootstrap_external>", line 678, in exec_module
  File "<frozen importlib._bootstrap>", line 219, in _call_with_frames_removed
  File "/root/flask_api_demo/app.py", line 5, in <module>
    import pysftp
ModuleNotFoundError: No module named 'pysftp'
[2020-10-20 06:19:59 +0000] [1268] [INFO] Worker exiting (pid: 1268)
[2020-10-20 06:40:05 +0000] [1254] [INFO] Starting gunicorn 20.0.4
[2020-10-20 06:40:05 +0000] [1254] [INFO] Listening at: http://0.0.0.0:5000 (1254)
[2020-10-20 06:40:05 +0000] [1254] [INFO] Using worker: sync
[2020-10-20 06:40:05 +0000] [1261] [INFO] Booting worker with pid: 1261
[2020-10-20 06:40:05 +0000] [1262] [INFO] Booting worker with pid: 1262
[2020-10-20 06:40:05 +0000] [1264] [INFO] Booting worker with pid: 1264
[2020-10-20 06:40:05 +0000] [1265] [INFO] Booting worker with pid: 1265
[2020-10-20 06:40:06 +0000] [1267] [INFO] Booting worker with pid: 1267
[2020-10-20 06:40:06 +0000] [1255] [INFO] Starting gunicorn 20.0.4
[2020-10-20 06:40:06 +0000] [1255] [INFO] Listening at: http://0.0.0.0:5000 (1255)
[2020-10-20 06:40:06 +0000] [1255] [INFO] Using worker: sync
[2020-10-20 06:40:06 +0000] [1262] [INFO] Booting worker with pid: 1262
[2020-10-20 06:40:06 +0000] [1269] [INFO] Booting worker with pid: 1269
[2020-10-20 06:40:06 +0000] [1263] [INFO] Booting worker with pid: 1263
[2020-10-20 06:40:06 +0000] [1264] [INFO] Booting worker with pid: 1264
[2020-10-20 06:40:06 +0000] [1266] [INFO] Booting worker with pid: 1266
[2020-10-20 06:40:06 +0000] [1269] [INFO] Booting worker with pid: 1269
[2020-10-20 06:40:06 +0000] [1270] [INFO] Booting worker with pid: 1270
[2020-10-20 06:41:29 +0000] [1254] [INFO] Starting gunicorn 20.0.4
[2020-10-20 06:41:29 +0000] [1254] [INFO] Listening at: http://0.0.0.0:5000 (1254)
[2020-10-20 06:41:29 +0000] [1254] [INFO] Using worker: sync
[2020-10-20 06:41:29 +0000] [1254] [INFO] Starting gunicorn 20.0.4
[2020-10-20 06:41:29 +0000] [1254] [INFO] Listening at: http://0.0.0.0:5000 (1254)
[2020-10-20 06:41:29 +0000] [1254] [INFO] Using worker: sync
[2020-10-20 06:41:29 +0000] [1261] [INFO] Booting worker with pid: 1261
[2020-10-20 06:41:29 +0000] [1261] [INFO] Booting worker with pid: 1261
[2020-10-20 06:41:29 +0000] [1262] [INFO] Booting worker with pid: 1262
[2020-10-20 06:41:29 +0000] [1262] [INFO] Booting worker with pid: 1262
[2020-10-20 06:41:29 +0000] [1263] [INFO] Booting worker with pid: 1263
[2020-10-20 06:41:29 +0000] [1264] [INFO] Booting worker with pid: 1264
[2020-10-20 06:41:29 +0000] [1265] [INFO] Booting worker with pid: 1265
[2020-10-20 06:41:29 +0000] [1267] [INFO] Booting worker with pid: 1267
[2020-10-20 06:41:29 +0000] [1268] [INFO] Booting worker with pid: 1268
[2020-10-20 06:41:29 +0000] [1267] [INFO] Booting worker with pid: 1267
[2020-10-20 06:41:29 +0000] [1269] [INFO] Booting worker with pid: 1269
[2020-10-20 06:41:29 +0000] [1269] [INFO] Booting worker with pid: 1269
[2020-10-20 06:42:44 +0000] [1254] [CRITICAL] WORKER TIMEOUT (pid:1267)
[2020-10-20 06:42:44 +0000] [1267] [INFO] Worker exiting (pid: 1267)
[2020-10-20 06:42:44 +0000] [1311] [INFO] Booting worker with pid: 1311
[2020-10-20 06:43:27 +0000] [1254] [CRITICAL] WORKER TIMEOUT (pid:1262)
[2020-10-20 06:43:27 +0000] [1254] [CRITICAL] WORKER TIMEOUT (pid:1268)
[2020-10-20 06:43:27 +0000] [1262] [INFO] Worker exiting (pid: 1262)
[2020-10-20 06:43:27 +0000] [1268] [INFO] Worker exiting (pid: 1268)
[2020-10-20 06:43:27 +0000] [1321] [INFO] Booting worker with pid: 1321
[2020-10-20 06:43:27 +0000] [1323] [INFO] Booting worker with pid: 1323
